Workbook

Sheet Intake
A1: ASSIGNMENT INTAKE FORM
A2: Key | B2: Value ← fill here | C2: Hint | D2: Status
A3: ▶ EXPORT JSON — see ExportJSON_macro.txt to enable this button in Excel
A4: Output: {FILE_NO}_variables.json in the same folder as this workbook
A5: ASSIGNMENT
A6: FILE_NO | B6: DEMO-001 | C6: e.g. DEMO-001 | D6: =IF(B6<>"","✓","—") -> ✓
A7: REPORT_DATE | B7: June 26, 2026 | C7: e.g. June 26, 2026 | D7: =IF(B7<>"","✓","—") -> ✓
A8: ENGAGEMENT_DATE | B8: June 26, 2026 | C8: e.g. June 26, 2026 | D8: =IF(B8<>"","✓","—") -> ✓
A9: EFFECTIVE_DATE | B9: May 28, 2026 | C9: e.g. June 1, 2026 | D9: =IF(B9<>"","✓","—") -> ✓
A10: DELIVERY_DATE | B10: June 26, 2026 | C10: e.g. July 10, 2026 | D10: =IF(B10<>"","✓","—") -> ✓
A11: TURNAROUND_DAYS | C11: e.g. 10 | D11: =IF(B11<>"","✓","—") -> —
A12: CLIENT & CONTACT
A13: CLIENT_NAME | B13: Northstar Example Holdings, LLC | C13: Legal entity name | D13: =IF(B13<>"","✓","—") -> ✓
A14: CONTACT_NAME | B14: Jordan Example | C14: Full name | D14: =IF(B14<>"","✓","—") -> ✓
A15: CONTACT_SALUTATION | B15: Ms. Example | C15: e.g. Mr. Smith | D15: =IF(B15<>"","✓","—") -> ✓
A16: CLIENT_ADDR1 | B16: 1000 Demonstration Plaza, Suite 200 | C16: Street address | D16: =IF(B16<>"","✓","—") -> ✓
A17: CLIENT_ADDR2 | B17: Sample City, Alabama 35000 | C17: City, State ZIP | D17: =IF(B17<>"","✓","—") -> ✓
A18: INTENDED_USE | B18: Internal Decision Making | C18: e.g. Mortgage financing | D18: =IF(B18<>"","✓","—") -> ✓
A19: PROPERTY
A20: PROPERTY_ADDRESS | B20: 100 Example Commerce Way | C20: Street address | D20: =IF(B20<>"","✓","—") -> ✓
A21: PROPERTY_CITY | B21: Sample City | C21: e.g. Test Metro | D21: =IF(B21<>"","✓","—") -> ✓
A22: PROPERTY_ZIP | B22: 35000 | C22: e.g. 35203 | D22: =IF(B22<>"","✓","—") -> ✓
A23: PROPERTY_COUNTY | B23: Example County | C23: e.g. Example | D23: =IF(B23<>"","✓","—") -> ✓
A24: PROPERTY_STATE | B24: Alabama | C24: e.g. Alabama
A25: PARCEL_ID | C25: Tax parcel number | D25: =IF(B24<>"","✓","—") -> ✓
A26: PROPERTY_SUBTYPE_TABLE | B26: Multi-Tenant Office | C26: e.g. Multi-Tenant Office | D26: =IF(B25<>"","✓","—") -> —
A27: PROPERTY_RIGHTS | B27: Leased Fee Estate | C27: e.g. Fee Simple | D27: =IF(B26<>"","✓","—") -> ✓
A28: REPORT_TYPE | B28: Appraisal Report | C28: e.g. Appraisal Report | D28: =IF(B28<>"","✓","—") -> ✓
A29: PHYSICAL CHARACTERISTICS
A30: YEAR_BUILT | B30: 1980 | C30: e.g. 1985 | D30: =IF(B29<>"","✓","—") -> —
A31: YEAR_RENOVATED | C31: Leave blank if N/A | D31: =IF(B30<>"","✓","—") -> ✓
A32: GBA | B32: 22,668 | C32: Gross Building Area | D32: =IF(B31<>"","✓","—") -> —
A33: NRA | C33: Net Rentable Area | D33: =IF(B32<>"","✓","—") -> ✓
A34: LAND_AREA_SF | D34: =IF(B33<>"","✓","—") -> —
A35: LAND_AREA_AC | D35: =IF(B34<>"","✓","—") -> —
A36: NUM_UNITS | D36: =IF(B35<>"","✓","—") -> —
A37: NUM_FLOORS | D37: =IF(B36<>"","✓","—") -> —
A38: OCCUPANCY_RATE | C38: e.g. 85% | D38: =IF(B37<>"","✓","—") -> —
A39: PARKING_SPACES | D39: =IF(B38<>"","✓","—") -> —
A40: ZONING | C40: e.g. B-2 | D40: =IF(B39<>"","✓","—") -> —
...

Sheet sales
B2: SUBJECT PROPERTY REFERENCE
B3: Address | C3: City | D3: GBA (SF) | E3: Year Built | F3: Property Type | G3: Zoning | H3: Class | I3: Median HH Income | J3: Population | K3: Flood Zone | L3: LTB Ratio
B4: =Intake!B20 -> 100 Example Commerce Way | C4: =Intake!B21 -> Sample City | D4: =Intake!B32 -> 22,668 | E4: =Intake!B30 -> 1980 | F4: =Intake!B26 -> Multi-Tenant Office | G4: =Intake!B40 -> 0 | H4: =Intake!B112 -> Class B | K4: =Intake!B147 -> Zone X
B7: COMPARABLE SALES DATA
B8: Sale No. | C8: Sale Date | D8: Location | E8: Sale Price | F8: GBA (SF) | G8: $/SF | H8: Overall Rate | I8: NOI $/SF | J8: Flood Zone | K8: LTB Ratio | L8: Year Built
B9: 1 | G9: =E9/F9 -> #DIV/0!
B10: 2 | G10: =E10/F10 -> #DIV/0!
B11: 3 | G11: =E11/F11 -> #DIV/0!
B12: 4 | G12: =E12/F12 -> #DIV/0!
B13: 5 | G13: =E13/F13 -> #DIV/0!
B14: 6 | G14: =E14/F14 -> #DIV/0!
B15: 7 | G15: =E15/F15 -> #DIV/0!
B18: ADJUSTMENT GRID
B19: Sale No. | C19: Unadj. $/SF | D19: Market Adj. | E19: Adj. $/SF | F19: Comp GBA (SF) | G19: Size Adj. | H19: Location Adj. | I19: Net Adj. | J19: Indicated $/SF
B20: =B9 -> 1 | C20: =G9 -> #DIV/0! | D20: 0 | E20: =C20*(1+D20) -> #DIV/0! | F20: =F9 -> 0 | G20: 0 | H20: 0 | I20: =G20+H20 -> 0 | J20: =ROUND(E20*(1+I20),2) -> #DIV/0!
B21: =B10 -> 2 | C21: =G10 -> #DIV/0! | D21: 0 | E21: =C21*(1+D21) -> #DIV/0! | F21: =F10 -> 0 | G21: 0 | H21: 0 | I21: =G21+H21 -> 0 | J21: =ROUND(E21*(1+I21),2) -> #DIV/0!
B22: =B11 -> 3 | C22: =G11 -> #DIV/0! | D22: 0 | E22: =C22*(1+D22) -> #DIV/0! | F22: =F11 -> 0 | G22: 0 | H22: 0 | I22: =G22+H22 -> 0 | J22: =ROUND(E22*(1+I22),2) -> #DIV/0!
B23: =B12 -> 4 | C23: =G12 -> #DIV/0! | D23: 0 | E23: =C23*(1+D23) -> #DIV/0! | F23: =F12 -> 0 | G23: 0 | H23: 0 | I23: =G23+H23 -> 0 | J23: =ROUND(E23*(1+I23),2) -> #DIV/0!
B24: =B13 -> 5 | C24: =G13 -> #DIV/0! | D24: 0 | E24: =C24*(1+D24) -> #DIV/0! | F24: =F13 -> 0 | G24: 0 | H24: 0 | I24: =G24+H24 -> 0 | J24: =ROUND(E24*(1+I24),2) -> #DIV/0!
B25: =B14 -> 6 | C25: =G14 -> #DIV/0! | D25: 0 | E25: =C25*(1+D25) -> #DIV/0! | F25: =F14 -> 0 | G25: 0 | H25: 0 | I25: =G25+H25 -> 0 | J25: =ROUND(E25*(1+I25),2) -> #DIV/0!
B26: =B15 -> 7 | C26: =G15 -> #DIV/0! | D26: 0 | E26: =C26*(1+D26) -> #DIV/0! | F26: =F15 -> 0 | G26: 0 | H26: 0 | I26: =G26+H26 -> 0 | J26: =ROUND(E26*(1+I26),2) -> #DIV/0!
B29: DEMOGRAPHICS (5-Mile Radius)
B30: Sale No. | C30: Median Income | D30: Population
B31: 1
B32: 2
B33: 3
B34: 4
B35: 5
B36: 6
B37: 7
B38: Average | C38: =AVERAGE(C31:C37) -> #DIV/0! | D38: =AVERAGE(D31:D37) -> #DIV/0!
B39: Subject | C39: =$I$4 -> 0 | D39: =$J$4 -> 0
B41: QUALITATIVE ANALYSIS
B42: Sale No. | C42: Median Income | D42: Population | E42: Access | F42: Visibility | G42: Quality | H42: Condition | I42: Age | J42: Flood Zone | K42: LTB | L42: Utility | M42: Overall | O42: Similar | P42: Superior | Q42: Inferior
B43: 1 | C43: =IF(C31>$I$4*1.1,"Superior",IF(C31<$I$4*0.9,"Inferior","Similar")) -> Similar | D43: =IF(D31>$J$4*1.1,"Superior",IF(D31<$J$4*0.9,"Inferior","Similar")) -> Similar | J43: =IF($K$4="No",IF(J9="No","Similar","Inferior"),IF(J9="No","Superior","Similar")) -> Similar | K43: =IF(K9>$L$4*1.1,"Superior",IF(K9<$L$4*0.9,"Inferior","Similar")) -> Similar
B44: 2 | C44: =IF(C32>$I$4*1.1,"Superior",IF(C32<$I$4*0.9,"Inferior","Similar")) -> Similar | D44: =IF(D32>$J$4*1.1,"Superior",IF(D32<$J$4*0.9,"Inferior","Similar")) -> Similar | J44: =IF($K$4="No",IF(J10="No","Similar","Inferior"),IF(J10="No","Superior","Similar")) -> Similar | K44: =IF(K10>$L$4*1.1,"Superior",IF(K10<$L$4*0.9,"Inferior","Similar")) -> Similar
B45: 3 | C45: =IF(C33>$I$4*1.1,"Superior",IF(C33<$I$4*0.9,"Inferior","Similar")) -> Similar | D45: =IF(D33>$J$4*1.1,"Superior",IF(D33<$J$4*0.9,"Inferior","Similar")) -> Similar | J45: =IF($K$4="No",IF(J11="No","Similar","Inferior"),IF(J11="No","Superior","Similar")) -> Similar | K45: =IF(K11>$L$4*1.1,"Superior",IF(K11<$L$4*0.9,"Inferior","Similar")) -> Similar
B46: 4 | C46: =IF(C34>$I$4*1.1,"Superior",IF(C34<$I$4*0.9,"Inferior","Similar")) -> Similar | D46: =IF(D34>$J$4*1.1,"Superior",IF(D34<$J$4*0.9,"Inferior","Similar")) -> Similar | J46: =IF($K$4="No",IF(J12="No","Similar","Inferior"),IF(J12="No","Superior","Similar")) -> Similar | K46: =IF(K12>$L$4*1.1,"Superior",IF(K12<$L$4*0.9,"Inferior","Similar")) -> Similar
B47: 5 | C47: =IF(C35>$I$4*1.1,"Superior",IF(C35<$I$4*0.9,"Inferior","Similar")) -> Similar | D47: =IF(D35>$J$4*1.1,"Superior",IF(D35<$J$4*0.9,"Inferior","Similar")) -> Similar | J47: =IF($K$4="No",IF(J13="No","Similar","Inferior"),IF(J13="No","Superior","Similar")) -> Similar | K47: =IF(K13>$L$4*1.1,"Superior",IF(K13<$L$4*0.9,"Inferior","Similar")) -> Similar
B48: 6 | C48: =IF(C36>$I$4*1.1,"Superior",IF(C36<$I$4*0.9,"Inferior","Similar")) -> Similar | D48: =IF(D36>$J$4*1.1,"Superior",IF(D36<$J$4*0.9,"Inferior","Similar")) -> Similar | J48: =IF($K$4="No",IF(J14="No","Similar","Inferior"),IF(J14="No","Superior","Similar")) -> Similar | K48: =IF(K14>$L$4*1.1,"Superior",IF(K14<$L$4*0.9,"Inferior","Similar")) -> Similar
...

Sheet cost
B2: COST APPROACH — DEPRECIATION ANALYSIS
B5: BUILDING REPRODUCTION COST (DIRECT COST)
B6: Item | C6: Value | D6: Units | E6: Notes
B7: Base Cost/SF (Marshall & Swift) | D7: $/SF | E7: ← Update per cost manual for current year
B8: GBA (SF) | D8: SF
B9: Area Size Adjustment | D9: mult. | E9: Applied to base cost
B10: Time/Local Conditions Adjustment | D10: mult. | E10: Adjust to current/local market
B11: Building Cost/SF (Adjusted) | C11: =B7*B9*B10 -> #VALUE! | D11: $/SF | E11: =B7*B9*B10 -> #VALUE!
B12: Total Reproduction Cost (Direct) | C12: =B8*B11 -> #VALUE! | D12: $ | E12: =B7*B8 * all adjustments -> #VALUE!
B14: PHYSICAL DETERIORATION — SHORT-LIVED ITEMS
B15: Component | C15: Cost New | D15: Eff. Age (Yrs) | E15: Typical Life (Yrs) | F15: % Depr. | G15: Value of Depr.
B16: HVAC | F16: =D16/E16 -> #DIV/0! | G16: =C16*F16 -> #DIV/0!
B17: Floor Cover | F17: =D17/E17 -> #DIV/0! | G17: =C17*F17 -> #DIV/0!
B18: Roof Cover | F18: =D18/E18 -> #DIV/0! | G18: =C18*F18 -> #DIV/0!
B19: Interior Fin. | F19: =D19/E19 -> #DIV/0! | G19: =C19*F19 -> #DIV/0!
B20: TOTAL SHORT-LIVED ITEMS | C20: =SUM(C16:C19) -> 0 | G20: =SUM(G16:G19) -> #DIV/0!
B22: SITE IMPROVEMENTS (DEPRECIATED SEPARATELY)
B23: Component | C23: Cost New | D23: Eff. Age (Yrs) | E23: Typical Life (Yrs) | F23: % Depr. | G23: Value of Depr.
B24: Landscaping / Retaining Wall | F24: =D24/E24 -> #DIV/0! | G24: =C24*F24 -> #DIV/0!
B25: Signage / Lighting | F25: =D25/E25 -> #DIV/0! | G25: =C25*F25 -> #DIV/0!
B26: Paving / Curbing | F26: =D26/E26 -> #DIV/0! | G26: =C26*F26 -> #DIV/0!
B27: Site Work / Utilities | F27: =D27/E27 -> #DIV/0! | G27: =C27*F27 -> #DIV/0!
B28: TOTAL SITE IMPROVEMENTS | C28: =SUM(C24:C27) -> 0 | G28: =SUM(G24:G27) -> #DIV/0!
B30: PHYSICAL DETERIORATION — LONG-LIVED ITEMS (AGE-LIFE METHOD)
B31: Item | C31: Value
B32: Total Reproduction Cost (Direct) | C32: =cost!C12 -> #VALUE!
B33: Less: Short-Lived Items (Cost New) | C33: =C20 -> 0
B34: Long-Lived Items Cost | C34: =C32-C33 -> #VALUE!
B35: Effective Age (years) | C35: ← Appraiser judgment
B36: Total Economic Life (years)
B37: Depreciation Rate (EA / EL) | C37: =C35/C36 -> #VALUE!
B38: Long-Lived Depreciation | C38: =C34*C37 -> #VALUE!
B40: COST APPROACH — VALUE SUMMARY
B41: Values reference cost_approach and land_sales tabs. Change inputs there.
B43: Item | C43: Amount
B44: LAND VALUE
B45: Concluded Land Value (from land_sales tab) | C45: =land!d26 -> #NAME?
B47: IMPROVEMENTS — REPRODUCTION COST
B48: Total Reproduction Cost (Direct) | C48: =cost!C12 -> #VALUE!
B49: LESS: DEPRECIATION
...

Sheet noi_adj
B2: NOI ADJUSTMENT — COMPARABLE SALES
B3: Sale No. | C3: GBA (SF) | D3: Sale ($/SF) | E3: NOI/SF (Comp) | F3: NOI/SF (Subject) | G3: NOI Adj. Factor | H3: Adj. Indicated ($/SF)
B4: 1
B5: 2
B6: 3
B7: 4
B8: 5
B9: 6
B11: Note: N/A = comp lacks reliable income data.

Sheet cap_rates
B2: Comparable Sales (Implied Cap Rates)
B3: Sale | C3: Sale Date | D3: Sale Price | E3: NOI | F3: Implied Rate
E4: =F4*D4 -> 0
E5: =F5*D5 -> 0
E6: =F6*D6 -> 0
E7: =F7*D7 -> 0
B8: Indicated:

Sheet pgi_calc
B2: POTENTIAL GROSS INCOME — MARKET RENT CALCULATION
B3: PGI = Total GBA at market rent (stabilized leased fee basis). Actual collections shown for reference only.
B5: Market Rent Assumption ($/SF): | D5: 12 | E5: ← Update this cell to recalculate PGI
B7: Unit | C7: Tenant | D7: Status | E7: Size (SF) | F7: Mkt Rate ($/SF) | G7: Mkt PGI (Annual) | H7: Actual Rate | I7: Actual Annual
F8: =$D$5 -> 12 | G8: =E8*F8 -> 0
F9: =$D$5 -> 12 | G9: =E9*F9 -> 0
F10: =$D$5 -> 12 | G10: =E10*F10 -> 0
F11: =$D$5 -> 12 | G11: =E11*F11 -> 0
F12: =$D$5 -> 12 | G12: =E12*F12 -> 0
F13: =$D$5 -> 12 | G13: =E13*F13 -> 0
F14: =$D$5 -> 12 | G14: =E14*F14 -> 0
F15: =$D$5 -> 12 | G15: =E15*F15 -> 0
F16: =$D$5 -> 12 | G16: =E16*F16 -> 0
B17: TOTALS | E17: =SUM(E8:E16) -> 0 | G17: =SUM(G8:G16) -> 0 | I17: =SUM(I8:I16) -> 0
B18: CONCLUDED PGI (feeds Income Summary): | G18: =G17 -> 0
B19: Change market rent in D5 → PGI updates → income_summary!D5 updates → NOI/Value update automatically.

Sheet lease_comps
B2: LEASE COMPARABLE ANALYSIS
B3: Comp No. | C3: Location | D3: Size (SF) | E3: Rate ($/SF) | F3: Lease Type | G3: Begin | H3: End | I3: Tenant
B4: 1
B5: 2
B6: 3
B7: 4
B8: 5
B9: 6
B10: 7
B11: 8
B12: 9
B13: 10
B14: 11
B15: 12
B16: MEAN

Sheet lease_metrics
B2: LEASE RATE SUMMARY ($/SF)
B3: Metric | C3: Triple-Net | D3: Full Service
B4: Low | C4: 12 | D4: 12.5
B5: Median | C5: 14.5 | D5: 13.5
B6: High | C6: 17 | D6: 16
B7: Mean | C7: 14.278333 | D7: 14.28
B8: Count | C8: 6 | D8: 5
B10: LEASE SIZE SUMMARY (SF)
B11: Metric | C11: Triple-Net | D11: Full Service
B12: Low | C12: 1063 | D12: 899
B13: Median | C13: 2445 | D13: 1062
B14: High | C14: 5300 | D14: 4189
B15: Mean | C15: 2865.5 | D15: 1729.8

Sheet qualitative_analysis
B2: LEASE COMPARABLE — QUALITATIVE ANALYSIS
B4: Comp No. | C4: Location | D4: Rate ($/SF) | E4: Location | F4: Quality | G4: Condition | H4: Size | I4: Lease Terms | J4: Overall
B5: 1
B6: 2
B7: 3
B8: 4
B9: 5
B10: 6
B11: 7
B12: 8
B13: 9
B14: 10
B15: 11
B16: 12
B18: MARKET RENT CONCLUSION
B19: Range of Comparable Rates:
B20: Most Comparable Comps
B21: Size Adjustment:
B22: Concluded Market Rent:
B24: Color Key: | C24: Superior | D24: Similar | E24: Inferior

Sheet subject_units
B2: SUBJECT PROPERTY — RENT ROLL
B3: Unit | C3: Tenant | D3: Size (SF) | E3: Monthly Rent | F3: Annual Rent | G3: Rate ($/SF) | H3: Lease Start | I3: Lease End
B13: TOTALS / AVERAGES
C14: Occupied Only

Sheet expense_comp
B2: OPERATING EXPENSE COMPARISON
B3: Benchmarks from CoStar/BOMA survey data. Subject estimates derived from market benchmarks and appraiser judgment. Values feed Income Summary.
B5: Expense Category | C5: Demo North $/SF | D5: Demo North Subj. Estimate | E5: Test Metro Mkt $/SF | F5: Test Metro Mkt Subj. Estimate | G5: Subject Concluded $/SF | H5: Subject Concluded Annual
B6: Management | C6: 0.36 | D6: 8160.48 | E6: 0.62 | F6: 14054.16 | G6: % of EGI | H6: (formula-driven in Income Summary)
B7: Ad Valorem Taxes | C7: 0.89 | D7: 20174.52 | E7: 1.01 | F7: 22894.68 | G7: 1.2717 | H7: 28827
B8: Insurance | C8: 0.47 | D8: 10653.96 | E8: 0.25 | F8: 5667 | G8: 0.3309 | H8: 7500
B9: Utilities | C9: 2.38 | D9: 53949.84 | E9: 2.34 | F9: 53043.12 | G9: 2.316 | H9: 52500
B10: Maintenance & Repairs | C10: 1.94 | D10: 43975.92 | E10: 0.97 | F10: 21987.96 | G10: 0.9926 | H10: 22500
B11: Reserves for Replacement | C11: 0.07 | D11: 1586.76 | E11: 0.07 | F11: 1586.76 | G11: 0.0662 | H11: 1500
B12: Professional Fees & Misc. | C12: 0.04 | D12: 906.72 | E12: 0.04 | F12: 906.72 | G12: 0.0441 | H12: 1000
B13: TOTALS | D13: =SUM(D6:D12) -> 139408.2 | F13: =SUM(F6:F12) -> 120140.4 | H13: =SUM(H6:H12) -> 113827
B14: Note: Management excluded from totals (percentage-based in Income Summary). Blue cells are editable inputs — update Subject Concluded Annual to adjust expense assumptions.

Sheet income_summary
B2: INCOME APPROACH — DIRECT CAPITALIZATION
B3: Income / Expense Item | C3: Rate / Basis | D3: Amount
B4: Income
B5: Potential Gross Income | D5: =pgi_calc!G17 -> 0
B6: Expense Reimbursements | D6: 62797
B7: Less: Vacancy & Credit Loss | C7: 0.2 | D7: =-C7*(D5+D6) -> -12559.4
B8: Effective Gross Income | D8: =D5+D6+D7 -> 50237.6
B9: Operating Expenses
B10: Management | C10: 0.06 | D10: =C10*D8 -> 3014.256
B11: Ad Valorem Taxes | D11: =expense_comp!H8 -> 7500
B12: Insurance | D12: =expense_comp!H9 -> 52500
B13: Utilities | D13: =expense_comp!H10 -> 22500
B14: Maintenance & Repairs | D14: =expense_comp!H11 -> 1500
B15: Reserves for Replacement | D15: =expense_comp!H12 -> 1000
B16: Professional Fees & Misc. | D16: =expense_comp!H13 -> 113827
B17: Total Operating Expenses | C17: =D17/D8 -> 4.0177329 | D17: =SUM(D10:D16) -> 201841.26
B18: Net Operating Income | D18: =D8-D17 -> -151603.66
B19: Capitalization Rate Applied | C19: 0.095
B20: Indicated Value by Income Approach | C20: =D18/C19 -> -1595828
B21: Rounded Value Indication | C21: =ROUND(C20/25000,0)*25000 -> -1600000
B22: Note: PGI = market-derived (not actual collections). Actual collections: see subject_units tab.

Sheet outputs
B2: OUTPUTS — SALES COMPARISON APPROACH
B3: Placeholder | C3: Raw Value | D3: Report Format (→ Word) | E3: Notes
B4: Summary Statistics
B5: SCA_COMP_UNIT_LOW | C5: =MIN(sales!G9:G15) -> #DIV/0! | D5: ="$"&TEXT(C5,"#,##0.00")&" per SF" -> #DIV/0! | E5: Unadj. low $/SF
B6: SCA_COMP_UNIT_HIGH | C6: =MAX(sales!G9:G15) -> #DIV/0! | D6: ="$"&TEXT(C6,"#,##0.00")&" per SF" -> #DIV/0! | E6: Unadj. high $/SF
B7: SCA_COMP_UNIT_MEDIAN | C7: =MEDIAN(sales!G9:G15) -> #DIV/0! | D7: ="$"&TEXT(C7,"#,##0.00")&" per SF" -> #DIV/0! | E7: Unadj. median $/SF
B8: SCA_ADJ_UNIT_LOW | C8: =MIN(sales!J20:J26) -> #DIV/0! | D8: ="$"&TEXT(C8,"#,##0.00")&" per SF" -> #DIV/0! | E8: Indicated low $/SF (adj.)
B9: SCA_ADJ_UNIT_HIGH | C9: =MAX(sales!J20:J26) -> #DIV/0! | D9: ="$"&TEXT(C9,"#,##0.00")&" per SF" -> #DIV/0! | E9: Indicated high $/SF (adj.)
B10: SCA_ADJ_UNIT_MEDIAN | C10: =MEDIAN(sales!J20:J26) -> #DIV/0! | D10: ="$"&TEXT(C10,"#,##0.00")&" per SF" -> #DIV/0! | E10: Indicated median $/SF (adj.)
B11: Report Placeholders
B12: Placeholder | C12: Raw Value | D12: Report Format (→ Word) | E12: Notes
B13: SCA_CONCLUDED_PSF | C13: =sales!C56 -> 0 | D13: ="$"&TEXT(C13,"#,##0.00")&" per SF" -> $0.00 per SF | E13: Concluded $/SF → multiply by subject GBA
B14: SCA_VALUE | C14: =sales!D56 -> 0 | D14: ="$"&TEXT(C14,"#,##0") -> $0 | E14: ← Round to nearest $25,000 before reporting
B15: SCA_ADJ_UNIT_MEAN | C15: =AVERAGE(sales!J20:J26) -> #DIV/0! | D15: ="$"&TEXT(C15,"#,##0.00")&" per SF" -> #DIV/0! | E15: Adj. mean $/SF
B16: SCA_COMP_UNIT_MEAN | C16: =AVERAGE(sales!G9:G15) -> #DIV/0! | D16: ="$"&TEXT(C16,"#,##0.00")&" per SF" -> #DIV/0! | E16: Unadj. mean $/SF
B17: SCA_COMP_SIZE_LOW | C17: =MIN(sales!F9:F15) -> 0 | D17: =TEXT(C17,"#,##0")&" SF" -> 0 SF | E17: Comp size low SF
B18: SCA_COMP_SIZE_HIGH | C18: =MAX(sales!F9:F15) -> 0 | D18: =TEXT(C18,"#,##0")&" SF" -> 0 SF | E18: Comp size high SF
B19: SCA_COMP_SIZE_MEAN | C19: =AVERAGE(sales!F9:F15) -> #DIV/0! | D19: =TEXT(C19,"#,##0")&" SF" -> #DIV/0! | E19: Comp size mean SF
B20: SCA_COMP_SIZE_MEDIAN | C20: =MEDIAN(sales!F9:F15) -> #VALUE! | D20: =TEXT(C20,"#,##0")&" SF" -> #VALUE! | E20: Comp size median SF
B21: SCA_ADJ_NARROW_LOW | D21: ="$"&TEXT(C21,"#,##0.00")&" per SF" -> $0.00 per SF | E21: Narrow range low — enter manually
B22: SCA_ADJ_NARROW_HIGH | D22: ="$"&TEXT(C22,"#,##0.00")&" per SF" -> $0.00 per SF | E22: Narrow range high — enter manually
B23: SCA_ADJ_NARROW_MEAN | D23: ="$"&TEXT(C23,"#,##0.00")&" per SF" -> $0.00 per SF | E23: Narrow range mean — enter manually
B24: SCA_ADJ_NARROW_MEDIAN | D24: ="$"&TEXT(C24,"#,##0.00")&" per SF" -> $0.00 per SF | E24: Narrow range median — enter manually
B25: SCA_ADJ_RELEVANT_MEAN | D25: ="$"&TEXT(C25,"#,##0.00")&" per SF" -> $0.00 per SF | E25: Most-relevant comps mean — enter manually
B26: SCA_ADJ_RELEVANT_MEDIAN | D26: ="$"&TEXT(C26,"#,##0.00")&" per SF" -> $0.00 per SF | E26: Most-relevant comps median — enter manually
B27: SCA_QUAL_CONCLUSION | D27: =IF(C27="","",C27) | E27: Qualitative conclusion text — enter manually
B29: OUTPUTS — CAP RATE ANALYSIS
B30: Placeholder | C30: Raw Value | D30: Report Format (→ Word) | E30: Notes
B31: Indicated Rate
B32: CAP_RATE_METHOD1 | C32: =IFERROR(AVERAGE(cap_rates!F4:F7),"") | D32: =TEXT(C32,"0.0%") | E32: Implied from comp sales
B33: Selected Rate (Report Placeholder)
B34: Placeholder | C34: Raw Value | D34: Report Format (→ Word) | E34: Notes
B35: CAP_RATE | C35: =income_summary!C19 -> 0.095 | D35: =TEXT(C35,"0.0%") -> 9.5% | E35: ← Set cap rate in income_summary tab (C19)
B38: PER-COMP DATA — for comp page automation
B39: Python iterates these rows (one per comp). Add/remove rows as comps change.
B40: Comp No. | C40: Sale Date | D40: Location | E40: Sale Price | F40: GBA (SF) | G40: $/SF | H40: Market Adj. | I40: Size Adj. | J40: Location Adj. | K40: Net Adj. | L40: Indicated $/SF
B41: =sales!B9 -> 1 | C41: =sales!C9 -> 0 | D41: =sales!D9 -> 0 | E41: =sales!E9 -> 0 | F41: =sales!F9 -> 0 | G41: =sales!G9 -> #DIV/0! | H41: =sales!D20 -> 0 | I41: =sales!G20 -> 0 | J41: =sales!H20 -> 0 | K41: =sales!I20 -> 0 | L41: =sales!J20 -> #DIV/0!
B42: =sales!B10 -> 2 | C42: =sales!C10 -> 0 | D42: =sales!D10 -> 0 | E42: =sales!E10 -> 0 | F42: =sales!F10 -> 0 | G42: =sales!G10 -> #DIV/0! | H42: =sales!D21 -> 0 | I42: =sales!G21 -> 0 | J42: =sales!H21 -> 0 | K42: =sales!I21 -> 0 | L42: =sales!J21 -> #DIV/0!
B43: =sales!B11 -> 3 | C43: =sales!C11 -> 0 | D43: =sales!D11 -> 0 | E43: =sales!E11 -> 0 | F43: =sales!F11 -> 0 | G43: =sales!G11 -> #DIV/0! | H43: =sales!D22 -> 0 | I43: =sales!G22 -> 0 | J43: =sales!H22 -> 0 | K43: =sales!I22 -> 0 | L43: =sales!J22 -> #DIV/0!
B44: =sales!B12 -> 4 | C44: =sales!C12 -> 0 | D44: =sales!D12 -> 0 | E44: =sales!E12 -> 0 | F44: =sales!F12 -> 0 | G44: =sales!G12 -> #DIV/0! | H44: =sales!D23 -> 0 | I44: =sales!G23 -> 0 | J44: =sales!H23 -> 0 | K44: =sales!I23 -> 0 | L44: =sales!J23 -> #DIV/0!
...

Sheet comp_data
A1: COMP_NO | B1: COMP_SUBMARKET | C1: COMP_ADDRESS_LINE1 | D1: COMP_ADDRESS_LINE2 | E1: COMP_PROPERTY_TYPE | F1: COMP_SALE_PRICE | G1: COMP_SALE_DATE | H1: COMP_GBA_SF | I1: COMP_PRICE_SF | J1: COMP_CAP_RATE | K1: COMP_YEAR_BUILT | L1: COMP_SITE_AREA | M1: COMP_STORIES | N1: COMP_CONSTRUCTION | O1: COMP_CONDITION | P1: COMP_ZONING | Q1: COMP_TOPOGRAPHY | R1: COMP_SHAPE | S1: COMP_FLOOD_ZONE | T1: COMP_ACCESS | U1: COMP_VISIBILITY | V1: COMP_UTILITIES | W1: COMP_GRANTOR | X1: COMP_GRANTEE | Y1: COMP_DEED_REF | Z1: COMP_VERIFICATION | AA1: COMP_NOI | AB1: COMP_NOI_SF | AC1: COMP_ANALYSIS | AD1: COMP_RELEVANCE | AE1: COMP_POPULATION | AF1: COMP_HH_INCOME | AG1: COMP_LIST_PRICE | AH1: COMP_PCT_DISCOUNT | AI1: COMP_TIME_ON_MARKET
A2: Sale No. N (e.g. Sale No. 1) | B2: Submarket name (e.g. Demo Hills) | C2: Street address | D2: City, State ZIP | E2: Property type label | F2: Sale price (e.g. $892,000) | G2: Sale date (e.g. 12/26/2025) | H2: GBA with SF (e.g. 9,780 SF) | I2: Price per SF (e.g. $91.26) | J2: Cap rate (e.g. 8.10% or N/A) | K2: Year built (e.g. 1988) | L2: Site area (e.g. ± 110,002 SF) | M2: Stories (e.g. One, Two) | N2: Construction type | O2: Condition (e.g. Average) | P2: Zoning (e.g. Office/Commercial) | Q2: Topography (e.g. Level) | R2: Shape (e.g. Irregular) | S2: Flood zone (e.g. Zone X) | T2: Access (e.g. Average) | U2: Visibility (e.g. Average) | V2: Utilities (e.g. All Public) | W2: Grantor name | X2: Grantee name | Y2: Deed reference number | Z2: Verification source | AA2: NOI (e.g. $72,293 or Not Available) | AB2: NOI per SF (e.g. $7.39 or Not Available) | AC2: Main analysis paragraph | AD2: Relevance sentence | AE2: Population (e.g. 132,176) | AF2: Median HH income (e.g. $94,659) | AG2: List price (e.g. $1,000,000) | AH2: % discount from list (e.g. 11%) | AI2: Time on market (e.g. 52 days)
A3: Sale No. 1 | B3: Demo Hills | C3: 200 Fictional Park Drive | D3: Demo Hills, Alabama 35001 | E3: Multi-Tenant Office | F3: $1,800,000 | G3: 03/15/2025 | H3: 24,000 SF | I3: $75.00 | J3: 9.25% | K3: 1985 | L3: ± 65,000 SF | M3: Two | N3: Brick and Steel | O3: Average | P3: Office/Commercial | Q3: Level | R3: Rectangular | S3: Zone X | T3: Good | U3: Good | V3: All Public | W3: Example Seller One, LLC | X3: Sample Buyer One, LLC | Y3: DEMO-DEED-001 | Z3: Fictional QA Fixture | AA3: $166,500 | AB3: $6.94 | AC3: This fictional sale represents a similarly sized multi-tenant office property with average condition and comparable utility. Its reported price and income metrics exist solely to exercise automated comp-page generation. | AD3: Useful fictional size and use comparison for software QA. | AE3: 125,000 | AF3: $82,000 | AG3: $1,950,000 | AH3: 8% | AI3: 64 days
A4: Sale No. 2 | B4: Example Heights | C4: 425 Sample Center Boulevard | D4: Example Heights, Alabama 35002 | E4: Multi-Tenant Office | F4: $1,550,000 | G4: 08/22/2024 | H4: 20,000 SF | I4: $77.50 | J4: 9.50% | K4: 1978 | L4: ± 58,000 SF | M4: One | N4: Masonry | O4: Average | P4: Commercial | Q4: Gently Sloping | R4: Irregular | S4: Zone X | T4: Average | U4: Good | V4: All Public | W4: Example Seller Two, LLC | X4: Sample Buyer Two, LLC | Y4: DEMO-DEED-002 | Z4: Fictional QA Fixture | AA4: $147,250 | AB4: $7.36 | AC4: This fictional sale is slightly smaller than the subject and reflects an older single-story office configuration. The record is synthetic and is not market evidence. | AD4: Useful fictional age and location comparison for software QA. | AE4: 98,000 | AF4: $76,500 | AG4: $1,700,000 | AH4: 9% | AI4: 91 days
A5: Sale No. 3 | B5: Test Metro | C5: 750 Demonstration Office Lane | D5: Test Metro, Alabama 35003 | E5: Multi-Tenant Office | F5: $2,100,000 | G5: 11/07/2024 | H5: 27,000 SF | I5: $77.78 | J5: 9.00% | K5: 1992 | L5: ± 72,000 SF | M5: Two | N5: Brick Veneer | O5: Good | P5: Office/Commercial | Q5: Level | R5: Rectangular | S5: Zone X | T5: Good | U5: Average | V5: All Public | W5: Example Seller Three, LLC | X5: Sample Buyer Three, LLC | Y5: DEMO-DEED-003 | Z5: Fictional QA Fixture | AA5: $189,000 | AB5: $7.00 | AC5: This fictional sale is larger and newer than the subject, with a good-condition office profile. All facts are invented for repeatable pipeline testing. | AD5: Useful fictional condition and size comparison for software QA. | AE5: 142,000 | AF5: $88,000 | AG5: $2,250,000 | AH5: 7% | AI5: 48 days
A6: Sale No. 4
A7: Sale No. 5
A8: Sale No. 6
A9: Sale No. 7

Sheet dilmore
A1: Dilmore Size Adjustment Table — Size Factor (A_c / A_s)
A2: A_c = Comparable GBA | A_s = Subject GBA | Factor = 1.00 means no size adjustment
A3: A_c / A_s | B3: 80% Curve | C3: 82.5% Curve | D3: 85% Curve | E3: 87.5% Curve | F3: 90% Curve | G3: Adj % (85%)
A4: 0.01 | B4: 0.23 | C4: 0.28 | D4: 0.34 | E4: 0.41 | F4: 0.5 | G4: -66.0%
A5: 0.02 | B5: 0.28 | C5: 0.34 | D5: 0.4 | E5: 0.47 | F5: 0.55 | G5: -60.0%
A6: 0.03 | B6: 0.32 | C6: 0.38 | D6: 0.44 | E6: 0.51 | F6: 0.59 | G6: -56.0%
A7: 0.04 | B7: 0.35 | C7: 0.41 | D7: 0.47 | E7: 0.54 | F7: 0.61 | G7: -53.0%
A8: 0.05 | B8: 0.38 | C8: 0.44 | D8: 0.49 | E8: 0.56 | F8: 0.63 | G8: -51.0%
A9: 0.06 | B9: 0.4 | C9: 0.46 | D9: 0.52 | E9: 0.58 | F9: 0.65 | G9: -48.0%
A10: 0.07 | B10: 0.42 | C10: 0.48 | D10: 0.54 | E10: 0.6 | F10: 0.67 | G10: -46.0%
A11: 0.08 | B11: 0.44 | C11: 0.5 | D11: 0.55 | E11: 0.61 | F11: 0.68 | G11: -45.0%
A12: 0.09 | B12: 0.46 | C12: 0.51 | D12: 0.57 | E12: 0.63 | F12: 0.69 | G12: -43.0%
A13: 0.1 | B13: 0.48 | C13: 0.53 | D13: 0.58 | E13: 0.64 | F13: 0.7 | G13: -42.0%
A14: 0.11 | B14: 0.49 | C14: 0.54 | D14: 0.6 | E14: 0.65 | F14: 0.71 | G14: -40.0%
A15: 0.12 | B15: 0.51 | C15: 0.56 | D15: 0.61 | E15: 0.66 | F15: 0.72 | G15: -39.0%
... A115: 100 | B115: 4.41 | C115: 3.59 | D115: 2.95 | E115: 2.43 | F115: 2.01 | G115: +195.0%

Sheet sca_adjustment_grid
A1: Sales Comparison Adjustment Grid — Dilmore Method
A3: Elasticity Curve: | B3: 85
A4: Subject GBA (SF): | B4: =Intake!B32 -> 22,668
A6: Comp | B6: Sale Price ($) | C6: Comp GBA (SF) | D6: Sale Price ($/SF) | E6: Sale Date | F6: Months to Eff. Date | G6: Monthly Mkt Rate | H6: Time Adj % | I6: Adjusted Price ($/SF) | J6: Ratio (Ac/As) | K6: Size Factor | L6: Size Adj % | M6: Size Adj $/SF | N6: Location Adj % | O6: Quality/Condition Adj % | P6: Utility Adj % | Q6: Net Adjustment % | R6: Indicated Value ($/SF) | S6: Notes
A7: Sale No. 1 | B7: 1800000 | C7: 24000 | D7: =IF(OR(B7="",C7=""),"",B7/C7) -> 75 | E7: 2025-03-15 | F7: =IF(OR(E7="",Intake!$B$9=""),"",(Intake!$B$9-E7)/30.4375) -> 14.422998 | G7: 0.005 | H7: =IF(OR(F7="",G7=""),"",F7*G7) -> 0.07211499 | I7: =IF(OR(D7="",H7=""),"",D7*(1+H7)) -> 80.408624 | J7: =IF(C7="","",IFERROR(C7/$B$4,"")) -> 1.0587612 | K7: 1.0118 | L7: 0.0118 | M7: =IF(OR(I7="",L7=""),"",I7*L7) -> 0.94882177 | N7: 0.02 | O7: -0.03 | P7: 0 | Q7: =IF(L7="","",L7+SUM(N7:P7)) -> 0.0018 | R7: =IF(OR(I7="",Q7=""),"",I7*(1+Q7)) -> 80.55336 | S7: 200 Fictional Park Drive, Demo Hills
A8: Sale No. 2 | B8: 1550000 | C8: 20000 | D8: =IF(OR(B8="",C8=""),"",B8/C8) -> 77.5 | E8: 2024-08-22 | F8: =IF(OR(E8="",Intake!$B$9=""),"",(Intake!$B$9-E8)/30.4375) -> 21.158111 | G8: 0.005 | H8: =IF(OR(F8="",G8=""),"",F8*G8) -> 0.10579055 | I8: =IF(OR(D8="",H8=""),"",D8*(1+H8)) -> 85.698768 | J8: =IF(C8="","",IFERROR(C8/$B$4,"")) -> 0.88230104 | K8: 0.9729 | L8: -0.0271 | M8: =IF(OR(I8="",L8=""),"",I8*L8) -> -2.3224366 | N8: -0.05 | O8: 0 | P8: 0.01 | Q8: =IF(L8="","",L8+SUM(N8:P8)) -> -0.0671 | R8: =IF(OR(I8="",Q8=""),"",I8*(1+Q8)) -> 79.948381 | S8: 425 Sample Center Boulevard, Example Heights
A9: Sale No. 3 | B9: 1650000 | C9: 21500 | D9: =IF(OR(B9="",C9=""),"",B9/C9) -> 76.744186 | E9: 2025-01-10 | F9: =IF(OR(E9="",Intake!$B$9=""),"",(Intake!$B$9-E9)/30.4375) -> 16.525667 | G9: 0.005 | H9: =IF(OR(F9="",G9=""),"",F9*G9) -> 0.082628337 | I9: =IF(OR(D9="",H9=""),"",D9*(1+H9)) -> 83.08543 | J9: =IF(C9="","",IFERROR(C9/$B$4,"")) -> 0.94847362 | K9: 0.9897 | L9: -0.0103 | M9: =IF(OR(I9="",L9=""),"",I9*L9) -> -0.85577993 | N9: 0 | O9: 0.02 | P9: 0 | Q9: =IF(L9="","",L9+SUM(N9:P9)) -> 0.0097 | R9: =IF(OR(I9="",Q9=""),"",I9*(1+Q9)) -> 83.891359 | S9: 310 Demonstration Ave, Sample City
A10: Sale No. 4 | D10: =IF(OR(B10="",C10=""),"",B10/C10) | F10: =IF(OR(E10="",Intake!$B$9=""),"",(Intake!$B$9-E10)/30.4375) | H10: =IF(OR(F10="",G10=""),"",F10*G10) | I10: =IF(OR(D10="",H10=""),"",D10*(1+H10)) | J10: =IF(C10="","",IFERROR(C10/$B$4,"")) | M10: =IF(OR(I10="",L10=""),"",I10*L10) | Q10: =IF(L10="","",L10+SUM(N10:P10)) | R10: =IF(OR(I10="",Q10=""),"",I10*(1+Q10))
A11: Sale No. 5 | D11: =IF(OR(B11="",C11=""),"",B11/C11) | F11: =IF(OR(E11="",Intake!$B$9=""),"",(Intake!$B$9-E11)/30.4375) | H11: =IF(OR(F11="",G11=""),"",F11*G11) | I11: =IF(OR(D11="",H11=""),"",D11*(1+H11)) | J11: =IF(C11="","",IFERROR(C11/$B$4,"")) | M11: =IF(OR(I11="",L11=""),"",I11*L11) | Q11: =IF(L11="","",L11+SUM(N11:P11)) | R11: =IF(OR(I11="",Q11=""),"",I11*(1+Q11))
A12: Sale No. 6 | D12: =IF(OR(B12="",C12=""),"",B12/C12) | F12: =IF(OR(E12="",Intake!$B$9=""),"",(Intake!$B$9-E12)/30.4375) | H12: =IF(OR(F12="",G12=""),"",F12*G12) | I12: =IF(OR(D12="",H12=""),"",D12*(1+H12)) | J12: =IF(C12="","",IFERROR(C12/$B$4,"")) | M12: =IF(OR(I12="",L12=""),"",I12*L12) | Q12: =IF(L12="","",L12+SUM(N12:P12)) | R12: =IF(OR(I12="",Q12=""),"",I12*(1+Q12))
A13: Sale No. 7 | D13: =IF(OR(B13="",C13=""),"",B13/C13) | F13: =IF(OR(E13="",Intake!$B$9=""),"",(Intake!$B$9-E13)/30.4375) | H13: =IF(OR(F13="",G13=""),"",F13*G13) | I13: =IF(OR(D13="",H13=""),"",D13*(1+H13)) | J13: =IF(C13="","",IFERROR(C13/$B$4,"")) | M13: =IF(OR(I13="",L13=""),"",I13*L13) | Q13: =IF(L13="","",L13+SUM(N13:P13)) | R13: =IF(OR(I13="",Q13=""),"",I13*(1+Q13))
A14: Sale No. 8 | D14: =IF(OR(B14="",C14=""),"",B14/C14) | F14: =IF(OR(E14="",Intake!$B$9=""),"",(Intake!$B$9-E14)/30.4375) | H14: =IF(OR(F14="",G14=""),"",F14*G14) | I14: =IF(OR(D14="",H14=""),"",D14*(1+H14)) | J14: =IF(C14="","",IFERROR(C14/$B$4,"")) | M14: =IF(OR(I14="",L14=""),"",I14*L14) | Q14: =IF(L14="","",L14+SUM(N14:P14)) | R14: =IF(OR(I14="",Q14=""),"",I14*(1+Q14))
A15: Sale No. 9 | D15: =IF(OR(B15="",C15=""),"",B15/C15) | F15: =IF(OR(E15="",Intake!$B$9=""),"",(Intake!$B$9-E15)/30.4375) | H15: =IF(OR(F15="",G15=""),"",F15*G15) | I15: =IF(OR(D15="",H15=""),"",D15*(1+H15)) | J15: =IF(C15="","",IFERROR(C15/$B$4,"")) | M15: =IF(OR(I15="",L15=""),"",I15*L15) | Q15: =IF(L15="","",L15+SUM(N15:P15)) | R15: =IF(OR(I15="",Q15=""),"",I15*(1+Q15))
A16: Sale No. 10 | D16: =IF(OR(B16="",C16=""),"",B16/C16) | F16: =IF(OR(E16="",Intake!$B$9=""),"",(Intake!$B$9-E16)/30.4375) | H16: =IF(OR(F16="",G16=""),"",F16*G16) | I16: =IF(OR(D16="",H16=""),"",D16*(1+H16)) | J16: =IF(C16="","",IFERROR(C16/$B$4,"")) | M16: =IF(OR(I16="",L16=""),"",I16*L16) | Q16: =IF(L16="","",L16+SUM(N16:P16)) | R16: =IF(OR(I16="",Q16=""),"",I16*(1+Q16))

Sheet land_adjustment_grid
A1: Land Sales Adjustment Grid
A2: Subject: 100 Example Commerce Way, Sample City — 55,452 SF (1.27 Ac), Zone X, C-5
A6: Comp | B6: Location | C6: Sale Price ($) | D6: Site Area (SF) | E6: Sale Price ($/SF) | F6: Sale Date | G6: Months to Eff. Date | H6: Monthly Mkt Rate | I6: Time Adj % | J6: Adjusted Price ($/SF) | K6: Location Adj % | L6: Topography Adj % | M6: Surrounding Land Uses Adj % | N6: Net Adjustment % | O6: Indicated Value ($/SF) | P6: Flood Zone | Q6: Zoning | R6: Notes
A7: Sale No. 1 | B7: 150 Fictional Commerce Pkwy, Sample City | C7: 450000 | D7: 48000 | E7: =IF(OR(C7="",D7=""),"",C7/D7) -> 9.375 | F7: 2025-05-01 | G7: =IF(OR(F7="",Intake!$B$9=""),"",(Intake!$B$9-F7)/30.4375) -> 12.87885 | H7: 0.004 | I7: =IF(OR(G7="",H7=""),"",G7*H7) -> 0.0515154 | J7: =IF(OR(E7="",I7=""),"",E7*(1+I7)) -> 9.8579569 | K7: 0.03 | L7: -0.02 | M7: 0 | N7: =IF(AND(K7="",L7="",M7=""),"",SUM(K7:M7)) -> 0.01 | O7: =IF(OR(J7="",N7=""),"",J7*(1+N7)) -> 9.9565364 | P7: X | Q7: C-5
A8: Sale No. 2 | B8: 275 Example Trade Center Rd, Sample City | C8: 380000 | D8: 42000 | E8: =IF(OR(C8="",D8=""),"",C8/D8) -> 9.047619 | F8: 2025-02-14 | G8: =IF(OR(F8="",Intake!$B$9=""),"",(Intake!$B$9-F8)/30.4375) -> 15.37577 | H8: 0.004 | I8: =IF(OR(G8="",H8=""),"",G8*H8) -> 0.06150308 | J8: =IF(OR(E8="",I8=""),"",E8*(1+I8)) -> 9.6040755 | K8: -0.04 | L8: 0 | M8: 0.01 | N8: =IF(AND(K8="",L8="",M8=""),"",SUM(K8:M8)) -> -0.03 | O8: =IF(OR(J8="",N8=""),"",J8*(1+N8)) -> 9.3159532
A9: Sale No. 3 | E9: =IF(OR(C9="",D9=""),"",C9/D9) | G9: =IF(OR(F9="",Intake!$B$9=""),"",(Intake!$B$9-F9)/30.4375) | I9: =IF(OR(G9="",H9=""),"",G9*H9) | J9: =IF(OR(E9="",I9=""),"",E9*(1+I9)) | N9: =IF(AND(K9="",L9="",M9=""),"",SUM(K9:M9)) | O9: =IF(OR(J9="",N9=""),"",J9*(1+N9))
A10: Sale No. 4 | E10: =IF(OR(C10="",D10=""),"",C10/D10) | G10: =IF(OR(F10="",Intake!$B$9=""),"",(Intake!$B$9-F10)/30.4375) | I10: =IF(OR(G10="",H10=""),"",G10*H10) | J10: =IF(OR(E10="",I10=""),"",E10*(1+I10)) | N10: =IF(AND(K10="",L10="",M10=""),"",SUM(K10:M10)) | O10: =IF(OR(J10="",N10=""),"",J10*(1+N10))
A11: Sale No. 5 | E11: =IF(OR(C11="",D11=""),"",C11/D11) | G11: =IF(OR(F11="",Intake!$B$9=""),"",(Intake!$B$9-F11)/30.4375) | I11: =IF(OR(G11="",H11=""),"",G11*H11) | J11: =IF(OR(E11="",I11=""),"",E11*(1+I11)) | N11: =IF(AND(K11="",L11="",M11=""),"",SUM(K11:M11)) | O11: =IF(OR(J11="",N11=""),"",J11*(1+N11))
A12: Sale No. 6 | E12: =IF(OR(C12="",D12=""),"",C12/D12) | G12: =IF(OR(F12="",Intake!$B$9=""),"",(Intake!$B$9-F12)/30.4375) | I12: =IF(OR(G12="",H12=""),"",G12*H12) | J12: =IF(OR(E12="",I12=""),"",E12*(1+I12)) | N12: =IF(AND(K12="",L12="",M12=""),"",SUM(K12:M12)) | O12: =IF(OR(J12="",N12=""),"",J12*(1+N12))
A13: Sale No. 7 | E13: =IF(OR(C13="",D13=""),"",C13/D13) | G13: =IF(OR(F13="",Intake!$B$9=""),"",(Intake!$B$9-F13)/30.4375) | I13: =IF(OR(G13="",H13=""),"",G13*H13) | J13: =IF(OR(E13="",I13=""),"",E13*(1+I13)) | N13: =IF(AND(K13="",L13="",M13=""),"",SUM(K13:M13)) | O13: =IF(OR(J13="",N13=""),"",J13*(1+N13))
A14: Sale No. 8 | E14: =IF(OR(C14="",D14=""),"",C14/D14) | G14: =IF(OR(F14="",Intake!$B$9=""),"",(Intake!$B$9-F14)/30.4375) | I14: =IF(OR(G14="",H14=""),"",G14*H14) | J14: =IF(OR(E14="",I14=""),"",E14*(1+I14)) | N14: =IF(AND(K14="",L14="",M14=""),"",SUM(K14:M14)) | O14: =IF(OR(J14="",N14=""),"",J14*(1+N14))
A15: Sale No. 9 | E15: =IF(OR(C15="",D15=""),"",C15/D15) | G15: =IF(OR(F15="",Intake!$B$9=""),"",(Intake!$B$9-F15)/30.4375) | I15: =IF(OR(G15="",H15=""),"",G15*H15) | J15: =IF(OR(E15="",I15=""),"",E15*(1+I15)) | N15: =IF(AND(K15="",L15="",M15=""),"",SUM(K15:M15)) | O15: =IF(OR(J15="",N15=""),"",J15*(1+N15))
A16: Sale No. 10 | E16: =IF(OR(C16="",D16=""),"",C16/D16) | G16: =IF(OR(F16="",Intake!$B$9=""),"",(Intake!$B$9-F16)/30.4375) | I16: =IF(OR(G16="",H16=""),"",G16*H16) | J16: =IF(OR(E16="",I16=""),"",E16*(1+I16)) | N16: =IF(AND(K16="",L16="",M16=""),"",SUM(K16:M16)) | O16: =IF(OR(J16="",N16=""),"",J16*(1+N16))
A17: MEAN | E17: =IFERROR(AVERAGE(E7:E16),"") -> 9.2113095 | J17: =IFERROR(AVERAGE(J7:J16),"") -> 9.7310162 | O17: =IFERROR(AVERAGE(O7:O16),"") -> 9.6362448
A19: LAND VALUE CONCLUSION
A20: Indicated Range ($/SF): | B20: =IFERROR(MIN(O7:O16),"") -> 9.3159532 | D20: =IFERROR(MAX(O7:O16),"") -> 9.9565364
A21: Concluded Land Value ($/SF): | B21: 9.25
A22: Site Area (SF): | B22: 55452
A23: Concluded Land Value: | B23: =B21*B22 -> 512931

Sheet sca_qualitative
A1: Qualitative Analysis Grid — Sales Comparison Approach
A3: Threshold (|Overall| below this = Similar): | B3: 0.3
A6: Comp | B6: Location | C6: Traffic | D6: MHI | E6: Population | F6: Access | G6: Visibility | H6: Quality | I6: Condition | J6: Flood Zone | K6: LTB | L6: Utility | M6: Overall | N6: Rating
A7: Sale No. 1 | B7: 200 Fictional Park Drive, Demo Hills | C7: 1 | D7: 0 | E7: 0 | F7: 0 | G7: 0 | H7: 0 | I7: 1 | J7: 0 | K7: 0 | L7: 0 | M7: =IFERROR(AVERAGE(C7:L7),"") -> 0.2 | N7: =IF(M7="","",IF(M7>$B$3,"Superior",IF(M7<-$B$3,"Inferior","Similar"))) -> Similar
A8: Sale No. 2 | B8: 425 Sample Center Boulevard, Example Heights | C8: 0 | D8: 0 | E8: 0 | F8: -1 | G8: 0 | H8: 0 | I8: 0 | J8: 0 | K8: 0 | L8: 0 | M8: =IFERROR(AVERAGE(C8:L8),"") -> -0.1 | N8: =IF(M8="","",IF(M8>$B$3,"Superior",IF(M8<-$B$3,"Inferior","Similar"))) -> Similar
A9: Sale No. 3 | B9: 310 Demonstration Ave, Sample City | C9: 0 | D9: 0 | E9: 0 | F9: 0 | G9: 0 | H9: 0 | I9: 0 | J9: 0 | K9: 0 | L9: 0 | M9: =IFERROR(AVERAGE(C9:L9),"") -> 0 | N9: =IF(M9="","",IF(M9>$B$3,"Superior",IF(M9<-$B$3,"Inferior","Similar"))) -> Similar
A10: Sale No. 4 | M10: =IFERROR(AVERAGE(C10:L10),"") | N10: =IF(M10="","",IF(M10>$B$3,"Superior",IF(M10<-$B$3,"Inferior","Similar")))
A11: Sale No. 5 | M11: =IFERROR(AVERAGE(C11:L11),"") | N11: =IF(M11="","",IF(M11>$B$3,"Superior",IF(M11<-$B$3,"Inferior","Similar")))
A12: Sale No. 6 | M12: =IFERROR(AVERAGE(C12:L12),"") | N12: =IF(M12="","",IF(M12>$B$3,"Superior",IF(M12<-$B$3,"Inferior","Similar")))
A13: Sale No. 7 | M13: =IFERROR(AVERAGE(C13:L13),"") | N13: =IF(M13="","",IF(M13>$B$3,"Superior",IF(M13<-$B$3,"Inferior","Similar")))
A14: Sale No. 8 | M14: =IFERROR(AVERAGE(C14:L14),"") | N14: =IF(M14="","",IF(M14>$B$3,"Superior",IF(M14<-$B$3,"Inferior","Similar")))
A15: Sale No. 9 | M15: =IFERROR(AVERAGE(C15:L15),"") | N15: =IF(M15="","",IF(M15>$B$3,"Superior",IF(M15<-$B$3,"Inferior","Similar")))
A16: Sale No. 10 | M16: =IFERROR(AVERAGE(C16:L16),"") | N16: =IF(M16="","",IF(M16>$B$3,"Superior",IF(M16<-$B$3,"Inferior","Similar")))
A18: # Superior: | B18: =COUNTIF(N7:N16,"Superior") -> 0 | C18: # Similar: | D18: =COUNTIF(N7:N16,"Similar") -> 3 | E18: # Inferior: | F18: =COUNTIF(N7:N16,"Inferior") -> 0

Sheet land_qualitative
A1: Qualitative Analysis Grid — Land Sales
A3: Threshold (|Overall| below this = Similar): | B3: 0.3
A6: Comp | B6: Location | C6: Topography | D6: Surrounding Land Uses | E6: Access | F6: Visibility | G6: Flood Zone | H6: Utility | I6: Overall | J6: Rating
A7: Sale No. 1 | B7: 150 Fictional Commerce Pkwy, Sample City | C7: 1 | D7: 0 | E7: 0 | F7: 0 | G7: 0 | H7: 0 | I7: =IFERROR(AVERAGE(C7:H7),"") -> 0.16666667 | J7: =IF(I7="","",IF(I7>$B$3,"Superior",IF(I7<-$B$3,"Inferior","Similar"))) -> Similar
A8: Sale No. 2 | B8: 275 Example Trade Center Rd, Sample City | C8: 0 | D8: 0 | E8: 0 | F8: 0 | G8: 0 | H8: 0 | I8: =IFERROR(AVERAGE(C8:H8),"") -> 0 | J8: =IF(I8="","",IF(I8>$B$3,"Superior",IF(I8<-$B$3,"Inferior","Similar"))) -> Similar
A9: Sale No. 3 | I9: =IFERROR(AVERAGE(C9:H9),"") | J9: =IF(I9="","",IF(I9>$B$3,"Superior",IF(I9<-$B$3,"Inferior","Similar")))
A10: Sale No. 4 | I10: =IFERROR(AVERAGE(C10:H10),"") | J10: =IF(I10="","",IF(I10>$B$3,"Superior",IF(I10<-$B$3,"Inferior","Similar")))
A11: Sale No. 5 | I11: =IFERROR(AVERAGE(C11:H11),"") | J11: =IF(I11="","",IF(I11>$B$3,"Superior",IF(I11<-$B$3,"Inferior","Similar")))
A12: Sale No. 6 | I12: =IFERROR(AVERAGE(C12:H12),"") | J12: =IF(I12="","",IF(I12>$B$3,"Superior",IF(I12<-$B$3,"Inferior","Similar")))
A13: Sale No. 7 | I13: =IFERROR(AVERAGE(C13:H13),"") | J13: =IF(I13="","",IF(I13>$B$3,"Superior",IF(I13<-$B$3,"Inferior","Similar")))
A14: Sale No. 8 | I14: =IFERROR(AVERAGE(C14:H14),"") | J14: =IF(I14="","",IF(I14>$B$3,"Superior",IF(I14<-$B$3,"Inferior","Similar")))
A15: Sale No. 9 | I15: =IFERROR(AVERAGE(C15:H15),"") | J15: =IF(I15="","",IF(I15>$B$3,"Superior",IF(I15<-$B$3,"Inferior","Similar")))
A16: Sale No. 10 | I16: =IFERROR(AVERAGE(C16:H16),"") | J16: =IF(I16="","",IF(I16>$B$3,"Superior",IF(I16<-$B$3,"Inferior","Similar")))
A18: # Superior: | B18: =COUNTIF(J7:J16,"Superior") -> 0 | C18: # Similar: | D18: =COUNTIF(J7:J16,"Similar") -> 2 | E18: # Inferior: | F18: =COUNTIF(J7:J16,"Inferior") -> 0
