Workbook

Sheet Intake
A1: ASSIGNMENT INTAKE FORM
A2: Key | B2: Value ← fill here | C2: Hint | D2: Status
A3: ▶ EXPORT JSON — see ExportJSON_macro.txt to enable this button in Excel
A4: Output: {FILE_NO}_variables.json in the same folder as this workbook
A5: ASSIGNMENT
A6: FILE_NO | C6: e.g. DEMO-001 | D6: =IF(B6<>"","✓","—")
A7: REPORT_DATE | C7: e.g. June 26, 2026 | D7: =IF(B7<>"","✓","—")
A8: ENGAGEMENT_DATE | C8: e.g. June 26, 2026 | D8: =IF(B8<>"","✓","—")
A9: EFFECTIVE_DATE | C9: e.g. June 1, 2026 | D9: =IF(B9<>"","✓","—")
A10: DELIVERY_DATE | C10: e.g. July 10, 2026 | D10: =IF(B10<>"","✓","—")
A11: TURNAROUND_DAYS | C11: e.g. 10 | D11: =IF(B11<>"","✓","—")
A12: CLIENT & CONTACT
A13: CLIENT_NAME | C13: Legal entity name | D13: =IF(B13<>"","✓","—")
A14: CONTACT_NAME | C14: Full name | D14: =IF(B14<>"","✓","—")
A15: CONTACT_SALUTATION | C15: e.g. Mr. Smith | D15: =IF(B15<>"","✓","—")
A16: CLIENT_ADDR1 | C16: Street address | D16: =IF(B16<>"","✓","—")
A17: CLIENT_ADDR2 | C17: City, State ZIP | D17: =IF(B17<>"","✓","—")
A18: INTENDED_USE | C18: e.g. Mortgage financing | D18: =IF(B18<>"","✓","—")
A19: PROPERTY
A20: PROPERTY_ADDRESS | C20: Street address | D20: =IF(B20<>"","✓","—")
A21: PROPERTY_CITY | C21: e.g. Test Metro | D21: =IF(B21<>"","✓","—")
A22: PROPERTY_ZIP | C22: e.g. 35203 | D22: =IF(B22<>"","✓","—")
A23: PROPERTY_COUNTY | C23: e.g. Example | D23: =IF(B23<>"","✓","—")
A24: PROPERTY_STATE | C24: e.g. Alabama
A25: PARCEL_ID | C25: Tax parcel number | D25: =IF(B24<>"","✓","—")
A26: PROPERTY_SUBTYPE_TABLE | C26: e.g. Multi-Tenant Office | D26: =IF(B25<>"","✓","—")
A27: PROPERTY_RIGHTS | C27: e.g. Fee Simple | D27: =IF(B26<>"","✓","—")
A28: REPORT_TYPE
A29: PHYSICAL CHARACTERISTICS
A30: YEAR_BUILT | C30: e.g. 1985 | D30: =IF(B29<>"","✓","—")
A31: YEAR_RENOVATED | C31: Leave blank if N/A | D31: =IF(B30<>"","✓","—")
A32: GBA | C32: Gross Building Area | D32: =IF(B31<>"","✓","—")
A33: NRA | C33: Net Rentable Area | D33: =IF(B32<>"","✓","—")
A34: LAND_AREA_SF | D34: =IF(B33<>"","✓","—")
A35: LAND_AREA_AC | D35: =IF(B34<>"","✓","—")
A36: NUM_UNITS | D36: =IF(B35<>"","✓","—")
A37: NUM_FLOORS | D37: =IF(B36<>"","✓","—")
A38: OCCUPANCY_RATE | C38: e.g. 85% | D38: =IF(B37<>"","✓","—")
A39: PARKING_SPACES | D39: =IF(B38<>"","✓","—")
A40: ZONING | C40: e.g. B-2 | D40: =IF(B39<>"","✓","—")
...

Sheet sales
B2: SUBJECT PROPERTY REFERENCE
B3: Address | C3: City | D3: GBA (SF) | E3: Year Built | F3: Property Type | G3: Zoning | H3: Class | I3: Median HH Income | J3: Population | K3: Flood Zone | L3: LTB Ratio
B4: =Intake!B20 | C4: =Intake!B21 | D4: =Intake!B32 | E4: =Intake!B30 | F4: =Intake!B26 | G4: =Intake!B40 | H4: =Intake!B112 | K4: =Intake!B147
B7: COMPARABLE SALES DATA
B8: Sale No. | C8: Sale Date | D8: Location | E8: Sale Price | F8: GBA (SF) | G8: $/SF | H8: Overall Rate | I8: NOI $/SF | J8: Flood Zone | K8: LTB Ratio | L8: Year Built
B9: 1 | G9: =E9/F9
B10: 2 | G10: =E10/F10
B11: 3 | G11: =E11/F11
B12: 4 | G12: =E12/F12
B13: 5 | G13: =E13/F13
B14: 6 | G14: =E14/F14
B15: 7 | G15: =E15/F15
B18: ADJUSTMENT GRID
B19: Sale No. | C19: Unadj. $/SF | D19: Market Adj. | E19: Adj. $/SF | F19: Comp GBA (SF) | G19: Size Adj. | H19: Location Adj. | I19: Net Adj. | J19: Indicated $/SF
B20: =B9 | C20: =G9 | D20: 0 | E20: =C20*(1+D20) | F20: =F9 | G20: 0 | H20: 0 | I20: =G20+H20 | J20: =ROUND(E20*(1+I20),2)
B21: =B10 | C21: =G10 | D21: 0 | E21: =C21*(1+D21) | F21: =F10 | G21: 0 | H21: 0 | I21: =G21+H21 | J21: =ROUND(E21*(1+I21),2)
B22: =B11 | C22: =G11 | D22: 0 | E22: =C22*(1+D22) | F22: =F11 | G22: 0 | H22: 0 | I22: =G22+H22 | J22: =ROUND(E22*(1+I22),2)
B23: =B12 | C23: =G12 | D23: 0 | E23: =C23*(1+D23) | F23: =F12 | G23: 0 | H23: 0 | I23: =G23+H23 | J23: =ROUND(E23*(1+I23),2)
B24: =B13 | C24: =G13 | D24: 0 | E24: =C24*(1+D24) | F24: =F13 | G24: 0 | H24: 0 | I24: =G24+H24 | J24: =ROUND(E24*(1+I24),2)
B25: =B14 | C25: =G14 | D25: 0 | E25: =C25*(1+D25) | F25: =F14 | G25: 0 | H25: 0 | I25: =G25+H25 | J25: =ROUND(E25*(1+I25),2)
B26: =B15 | C26: =G15 | D26: 0 | E26: =C26*(1+D26) | F26: =F15 | G26: 0 | H26: 0 | I26: =G26+H26 | J26: =ROUND(E26*(1+I26),2)
B29: DEMOGRAPHICS (5-Mile Radius)
B30: Sale No. | C30: Median Income | D30: Population
B31: 1
B32: 2
B33: 3
B34: 4
B35: 5
B36: 6
B37: 7
B38: Average | C38: =AVERAGE(C31:C37) | D38: =AVERAGE(D31:D37)
B39: Subject | C39: =$I$4 | D39: =$J$4
B41: QUALITATIVE ANALYSIS
B42: Sale No. | C42: Median Income | D42: Population | E42: Access | F42: Visibility | G42: Quality | H42: Condition | I42: Age | J42: Flood Zone | K42: LTB | L42: Utility | M42: Overall | O42: Similar | P42: Superior | Q42: Inferior
B43: 1 | C43: =IF(C31>$I$4*1.1,"Superior",IF(C31<$I$4*0.9,"Inferior","Similar")) | D43: =IF(D31>$J$4*1.1,"Superior",IF(D31<$J$4*0.9,"Inferior","Similar")) | J43: =IF($K$4="No",IF(J9="No","Similar","Inferior"),IF(J9="No","Superior","Similar")) | K43: =IF(K9>$L$4*1.1,"Superior",IF(K9<$L$4*0.9,"Inferior","Similar"))
B44: 2 | C44: =IF(C32>$I$4*1.1,"Superior",IF(C32<$I$4*0.9,"Inferior","Similar")) | D44: =IF(D32>$J$4*1.1,"Superior",IF(D32<$J$4*0.9,"Inferior","Similar")) | J44: =IF($K$4="No",IF(J10="No","Similar","Inferior"),IF(J10="No","Superior","Similar")) | K44: =IF(K10>$L$4*1.1,"Superior",IF(K10<$L$4*0.9,"Inferior","Similar"))
B45: 3 | C45: =IF(C33>$I$4*1.1,"Superior",IF(C33<$I$4*0.9,"Inferior","Similar")) | D45: =IF(D33>$J$4*1.1,"Superior",IF(D33<$J$4*0.9,"Inferior","Similar")) | J45: =IF($K$4="No",IF(J11="No","Similar","Inferior"),IF(J11="No","Superior","Similar")) | K45: =IF(K11>$L$4*1.1,"Superior",IF(K11<$L$4*0.9,"Inferior","Similar"))
B46: 4 | C46: =IF(C34>$I$4*1.1,"Superior",IF(C34<$I$4*0.9,"Inferior","Similar")) | D46: =IF(D34>$J$4*1.1,"Superior",IF(D34<$J$4*0.9,"Inferior","Similar")) | J46: =IF($K$4="No",IF(J12="No","Similar","Inferior"),IF(J12="No","Superior","Similar")) | K46: =IF(K12>$L$4*1.1,"Superior",IF(K12<$L$4*0.9,"Inferior","Similar"))
B47: 5 | C47: =IF(C35>$I$4*1.1,"Superior",IF(C35<$I$4*0.9,"Inferior","Similar")) | D47: =IF(D35>$J$4*1.1,"Superior",IF(D35<$J$4*0.9,"Inferior","Similar")) | J47: =IF($K$4="No",IF(J13="No","Similar","Inferior"),IF(J13="No","Superior","Similar")) | K47: =IF(K13>$L$4*1.1,"Superior",IF(K13<$L$4*0.9,"Inferior","Similar"))
B48: 6 | C48: =IF(C36>$I$4*1.1,"Superior",IF(C36<$I$4*0.9,"Inferior","Similar")) | D48: =IF(D36>$J$4*1.1,"Superior",IF(D36<$J$4*0.9,"Inferior","Similar")) | J48: =IF($K$4="No",IF(J14="No","Similar","Inferior"),IF(J14="No","Superior","Similar")) | K48: =IF(K14>$L$4*1.1,"Superior",IF(K14<$L$4*0.9,"Inferior","Similar"))
...

Sheet land
B2: COMPARABLE LAND SALES — SUMMARY
B3: Subject: 100 Example Commerce Way, Sample City — 55,452 SF (1.27 Ac), Zone X, C-5
B4: Sale No. | C4: Location | D4: Sale Date | E4: Sale Price | F4: Site Area (SF) | G4: Price/SF | H4: Flood Zone | I4: Zoning | J4: Shape
B5: 1 | G5: =E5/F5
B6: 2 | G6: =E6/F6
B7: 3 | G7: =E7/F7
B8: 4 | G8: =E8/F8
B9: 5 | G9: =E9/F9
B10: MEAN | E10: =AVERAGE(E5:E9) | F10: =AVERAGE(F5:F9) | G10: =AVERAGE(G5:G9)
B11: SUBJECT
B13: LAND SALES ADJUSTMENT GRID
B14: Sale No. | C14: Sale Date | D14: Price/SF | E14: Mkt Cond Adj. | F14: Adj. Price/SF | G14: Size Adj. | H14: Location Adj. | I14: Net Adj. | J14: Indicated $/SF
B15: 1 | F15: =D15*(1+E15) | J15: =F15*(1+I15)
B16: 2 | F16: =D16*(1+E16) | J16: =F16*(1+I16)
B17: 3 | F17: =D17*(1+E17) | J17: =F17*(1+I17)
B18: 4 | F18: =D18*(1+E18) | J18: =F18*(1+I18)
B19: 5 | F19: =D19*(1+E19) | J19: =F19*(1+I19)
B20: MEAN | D20: =AVERAGE(D15:D19) | F20: =AVERAGE(F15:F19) | J20: =AVERAGE(J15:J19)
B22: LAND VALUE CONCLUSION
B23: Indicated Range ($/SF): | D23: =MIN(J15:J19) | E23: to | F23: =MAX(J15:J19)
B24: Concluded Land Value ($/SF):
B25: Site Area (SF):
B26: Concluded Land Value: | D26: =D24*D25
B28: LAND SALES — ADJUSTMENT INPUTS
B29: Enter adjustment % for each comp (positive = upward, negative = downward, 0 = no adjustment). Notes are optional; used by AI narrative generator.
B30: Comp No. | C30: Location (auto-ref) | D30: Mkt Cond Adj % | E30: Mkt Cond Note | F30: Location Adj % | G30: Location Note | H30: Other Adj % | I30: Other Note | J30: Dilmore Size Adj %
B31: 1 | C31: Comp 1 Address | J31: =IFERROR(size_adj!D6,0)
B32: 2 | C32: Comp 2 Address | J32: =IFERROR(size_adj!D7,0)
B33: 3 | C33: Comp 3 Address | J33: =IFERROR(size_adj!D8,0)
B34: 4 | C34: Comp 4 Address | J34: =IFERROR(size_adj!D9,0)
B35: 5 | C35: Comp 5 Address | J35: =IFERROR(size_adj!D10,0)
B36: 6 | C36: Comp 6 Address | J36: =IFERROR(size_adj!D11,0)
B37: 7 | C37: Comp 7 Address | J37: =IFERROR(size_adj!D12,0)
B38: 8 | C38: Comp 8 Address | J38: =IFERROR(size_adj!D13,0)
B39: 9 | C39: Comp 9 Address | J39: =IFERROR(size_adj!D14,0)
B40: 10 | C40: Comp 10 Address | J40: =IFERROR(size_adj!D15,0)
B42: Note: Adjustment % should match values in the MARKET CHART adjustment grid. Narrative AI reads these inputs at deliver time.

Sheet cost
B2: COST APPROACH — DEPRECIATION ANALYSIS
B5: BUILDING REPRODUCTION COST (DIRECT COST)
B6: Item | C6: Value | D6: Units | E6: Notes
B7: Base Cost/SF (Marshall & Swift) | D7: $/SF | E7: ← Update per cost manual for current year
B8: GBA (SF) | D8: SF
B9: Area Size Adjustment | D9: mult. | E9: Applied to base cost
B10: Time/Local Conditions Adjustment | D10: mult. | E10: Adjust to current/local market
B11: Building Cost/SF (Adjusted) | C11: =B7*B9*B10 | D11: $/SF | E11: =B7*B9*B10
B12: Total Reproduction Cost (Direct) | C12: =B8*B11 | D12: $ | E12: =B7*B8 * all adjustments
B14: PHYSICAL DETERIORATION — SHORT-LIVED ITEMS
B15: Component | C15: Cost New | D15: Eff. Age (Yrs) | E15: Typical Life (Yrs) | F15: % Depr. | G15: Value of Depr.
B16: HVAC | F16: =D16/E16 | G16: =C16*F16
B17: Floor Cover | F17: =D17/E17 | G17: =C17*F17
B18: Roof Cover | F18: =D18/E18 | G18: =C18*F18
B19: Interior Fin. | F19: =D19/E19 | G19: =C19*F19
B20: TOTAL SHORT-LIVED ITEMS | C20: =SUM(C16:C19) | G20: =SUM(G16:G19)
B22: SITE IMPROVEMENTS (DEPRECIATED SEPARATELY)
B23: Component | C23: Cost New | D23: Eff. Age (Yrs) | E23: Typical Life (Yrs) | F23: % Depr. | G23: Value of Depr.
B24: Landscaping / Retaining Wall | F24: =D24/E24 | G24: =C24*F24
B25: Signage / Lighting | F25: =D25/E25 | G25: =C25*F25
B26: Paving / Curbing | F26: =D26/E26 | G26: =C26*F26
B27: Site Work / Utilities | F27: =D27/E27 | G27: =C27*F27
B28: TOTAL SITE IMPROVEMENTS | C28: =SUM(C24:C27) | G28: =SUM(G24:G27)
B30: PHYSICAL DETERIORATION — LONG-LIVED ITEMS (AGE-LIFE METHOD)
B31: Item | C31: Value
B32: Total Reproduction Cost (Direct) | C32: =cost!C12
B33: Less: Short-Lived Items (Cost New) | C33: =C20
B34: Long-Lived Items Cost | C34: =C32-C33
B35: Effective Age (years) | C35: ← Appraiser judgment
B36: Total Economic Life (years)
B37: Depreciation Rate (EA / EL) | C37: =C35/C36
B38: Long-Lived Depreciation | C38: =C34*C37
B40: COST APPROACH — VALUE SUMMARY
B41: Values reference cost_approach and land_sales tabs. Change inputs there.
B43: Item | C43: Amount
B44: LAND VALUE
B45: Concluded Land Value (from land_sales tab) | C45: =land!D26
B47: IMPROVEMENTS — REPRODUCTION COST
B48: Total Reproduction Cost (Direct) | C48: =cost!C12
B49: LESS: DEPRECIATION
...

Sheet noi_adj
B2: NOI ADJUSTMENT — COMPARABLE SALES
B3: Sale No. | C3: GBA (SF) | D3: Sale ($/SF) | E3: NOI/SF (Comp) | F3: NOI/SF (Subject) | G3: NOI Adj. Factor | H3: Adj. Indicated ($/SF)
B4: 1
B5: 2
B6: 3
B7: 4
B8: 5
B9: 6
B11: Note: N/A = comp lacks reliable income data.

Sheet cap_rates
B2: Comparable Sales (Implied Cap Rates)
B3: Sale | C3: Sale Date | D3: Sale Price | E3: NOI | F3: Implied Rate
E4: =F4*D4
E5: =F5*D5
E6: =F6*D6
E7: =F7*D7
B8: Indicated:

Sheet pgi_calc
B2: POTENTIAL GROSS INCOME — MARKET RENT CALCULATION
B3: PGI = Total GBA at market rent (stabilized leased fee basis). Actual collections shown for reference only.
B5: Market Rent Assumption ($/SF): | D5: 12 | E5: ← Update this cell to recalculate PGI
B7: Unit | C7: Tenant | D7: Status | E7: Size (SF) | F7: Mkt Rate ($/SF) | G7: Mkt PGI (Annual) | H7: Actual Rate | I7: Actual Annual
F8: =$D$5 | G8: =E8*F8
F9: =$D$5 | G9: =E9*F9
F10: =$D$5 | G10: =E10*F10
F11: =$D$5 | G11: =E11*F11
F12: =$D$5 | G12: =E12*F12
F13: =$D$5 | G13: =E13*F13
F14: =$D$5 | G14: =E14*F14
F15: =$D$5 | G15: =E15*F15
F16: =$D$5 | G16: =E16*F16
B17: TOTALS | E17: =SUM(E8:E16) | G17: =SUM(G8:G16) | I17: =SUM(I8:I16)
B18: CONCLUDED PGI (feeds Income Summary): | G18: =G17
B19: Change market rent in D5 → PGI updates → income_summary!D5 updates → NOI/Value update automatically.

Sheet lease_comps
B2: LEASE COMPARABLE ANALYSIS
B3: Comp No. | C3: Location | D3: Size (SF) | E3: Rate ($/SF) | F3: Lease Type | G3: Begin | H3: End | I3: Tenant
B4: 1
B5: 2
B6: 3
B7: 4
B8: 5
B9: 6
B10: 7
B11: 8
B12: 9
B13: 10
B14: 11
B15: 12
B16: MEAN

Sheet lease_metrics
B2: LEASE RATE SUMMARY ($/SF)
B3: Metric | C3: Triple-Net | D3: Full Service
B4: Low | C4: 12 | D4: 12.5
B5: Median | C5: 14.5 | D5: 13.5
B6: High | C6: 17 | D6: 16
B7: Mean | C7: 14.278333 | D7: 14.28
B8: Count | C8: 6 | D8: 5
B10: LEASE SIZE SUMMARY (SF)
B11: Metric | C11: Triple-Net | D11: Full Service
B12: Low | C12: 1063 | D12: 899
B13: Median | C13: 2445 | D13: 1062
B14: High | C14: 5300 | D14: 4189
B15: Mean | C15: 2865.5 | D15: 1729.8

Sheet qualitative_analysis
B2: LEASE COMPARABLE — QUALITATIVE ANALYSIS
B4: Comp No. | C4: Location | D4: Rate ($/SF) | E4: Location | F4: Quality | G4: Condition | H4: Size | I4: Lease Terms | J4: Overall
B5: 1
B6: 2
B7: 3
B8: 4
B9: 5
B10: 6
B11: 7
B12: 8
B13: 9
B14: 10
B15: 11
B16: 12
B18: MARKET RENT CONCLUSION
B19: Range of Comparable Rates:
B20: Most Comparable Comps
B21: Size Adjustment:
B22: Concluded Market Rent:
B24: Color Key: | C24: Superior | D24: Similar | E24: Inferior

Sheet subject_units
B2: SUBJECT PROPERTY — RENT ROLL
B3: Unit | C3: Tenant | D3: Size (SF) | E3: Monthly Rent | F3: Annual Rent | G3: Rate ($/SF) | H3: Lease Start | I3: Lease End
B13: TOTALS / AVERAGES
C14: Occupied Only

Sheet expense_comp
B2: OPERATING EXPENSE COMPARISON
B3: Benchmarks from CoStar/BOMA survey data. Subject estimates derived from market benchmarks and appraiser judgment. Values feed Income Summary.
B5: Expense Category | C5: Demo North $/SF | D5: Demo North Subj. Estimate | E5: Test Metro Mkt $/SF | F5: Test Metro Mkt Subj. Estimate | G5: Subject Concluded $/SF | H5: Subject Concluded Annual
B6: Management | C6: 0.36 | D6: 8160.48 | E6: 0.62 | F6: 14054.16 | G6: % of EGI | H6: (formula-driven in Income Summary)
B7: Ad Valorem Taxes | C7: 0.89 | D7: 20174.52 | E7: 1.01 | F7: 22894.68 | G7: 1.2717 | H7: 28827
B8: Insurance | C8: 0.47 | D8: 10653.96 | E8: 0.25 | F8: 5667 | G8: 0.3309 | H8: 7500
B9: Utilities | C9: 2.38 | D9: 53949.84 | E9: 2.34 | F9: 53043.12 | G9: 2.316 | H9: 52500
B10: Maintenance & Repairs | C10: 1.94 | D10: 43975.92 | E10: 0.97 | F10: 21987.96 | G10: 0.9926 | H10: 22500
B11: Reserves for Replacement | C11: 0.07 | D11: 1586.76 | E11: 0.07 | F11: 1586.76 | G11: 0.0662 | H11: 1500
B12: Professional Fees & Misc. | C12: 0.04 | D12: 906.72 | E12: 0.04 | F12: 906.72 | G12: 0.0441 | H12: 1000
B13: TOTALS | D13: =SUM(D6:D12) | F13: =SUM(F6:F12) | H13: =SUM(H6:H12)
B14: Note: Management excluded from totals (percentage-based in Income Summary). Blue cells are editable inputs — update Subject Concluded Annual to adjust expense assumptions.

Sheet income_summary
B2: INCOME APPROACH — DIRECT CAPITALIZATION
B3: Income / Expense Item | C3: Rate / Basis | D3: Amount
B4: Income
B5: Potential Gross Income | D5: =pgi_calc!G17
B6: Expense Reimbursements | D6: 62797
B7: Less: Vacancy & Credit Loss | C7: 0.2 | D7: =-C7*(D5+D6)
B8: Effective Gross Income | D8: =D5+D6+D7
B9: Operating Expenses
B10: Management | C10: 0.06 | D10: =C10*D8
B11: Ad Valorem Taxes | D11: =expense_comp!H8
B12: Insurance | D12: =expense_comp!H9
B13: Utilities | D13: =expense_comp!H10
B14: Maintenance & Repairs | D14: =expense_comp!H11
B15: Reserves for Replacement | D15: =expense_comp!H12
B16: Professional Fees & Misc. | D16: =expense_comp!H13
B17: Total Operating Expenses | C17: =D17/D8 | D17: =SUM(D10:D16)
B18: Net Operating Income | D18: =D8-D17
B19: Capitalization Rate Applied | C19: 0.095
B20: Indicated Value by Income Approach | C20: =D18/C19
B21: Rounded Value Indication | C21: =ROUND(C20/25000,0)*25000
B22: Note: PGI = market-derived (not actual collections). Actual collections: see subject_units tab.

Sheet outputs
B2: OUTPUTS — SALES COMPARISON APPROACH
B3: Placeholder | C3: Raw Value | D3: Report Format (→ Word) | E3: Notes
B4: Summary Statistics
B5: SCA_COMP_UNIT_LOW | C5: =MIN(sales!G9:G15) | D5: ="$"&TEXT(C5,"#,##0.00")&" per SF" | E5: Unadj. low $/SF
B6: SCA_COMP_UNIT_HIGH | C6: =MAX(sales!G9:G15) | D6: ="$"&TEXT(C6,"#,##0.00")&" per SF" | E6: Unadj. high $/SF
B7: SCA_COMP_UNIT_MEDIAN | C7: =MEDIAN(sales!G9:G15) | D7: ="$"&TEXT(C7,"#,##0.00")&" per SF" | E7: Unadj. median $/SF
B8: SCA_ADJ_UNIT_LOW | C8: =MIN(sales!J20:J26) | D8: ="$"&TEXT(C8,"#,##0.00")&" per SF" | E8: Indicated low $/SF (adj.)
B9: SCA_ADJ_UNIT_HIGH | C9: =MAX(sales!J20:J26) | D9: ="$"&TEXT(C9,"#,##0.00")&" per SF" | E9: Indicated high $/SF (adj.)
B10: SCA_ADJ_UNIT_MEDIAN | C10: =MEDIAN(sales!J20:J26) | D10: ="$"&TEXT(C10,"#,##0.00")&" per SF" | E10: Indicated median $/SF (adj.)
B11: Report Placeholders
B12: Placeholder | C12: Raw Value | D12: Report Format (→ Word) | E12: Notes
B13: SCA_CONCLUDED_PSF | C13: =sales!C56 | D13: ="$"&TEXT(C13,"#,##0.00")&" per SF" | E13: Concluded $/SF → multiply by subject GBA
B14: SCA_VALUE | C14: =sales!D56 | D14: ="$"&TEXT(C14,"#,##0") | E14: ← Round to nearest $25,000 before reporting
B15: SCA_ADJ_UNIT_MEAN | C15: =AVERAGE(sales!J20:J26) | D15: ="$"&TEXT(C15,"#,##0.00")&" per SF" | E15: Adj. mean $/SF
B16: SCA_COMP_UNIT_MEAN | C16: =AVERAGE(sales!G9:G15) | D16: ="$"&TEXT(C16,"#,##0.00")&" per SF" | E16: Unadj. mean $/SF
B17: SCA_COMP_SIZE_LOW | C17: =MIN(sales!F9:F15) | D17: =TEXT(C17,"#,##0")&" SF" | E17: Comp size low SF
B18: SCA_COMP_SIZE_HIGH | C18: =MAX(sales!F9:F15) | D18: =TEXT(C18,"#,##0")&" SF" | E18: Comp size high SF
B19: SCA_COMP_SIZE_MEAN | C19: =AVERAGE(sales!F9:F15) | D19: =TEXT(C19,"#,##0")&" SF" | E19: Comp size mean SF
B20: SCA_COMP_SIZE_MEDIAN | C20: =MEDIAN(sales!F9:F15) | D20: =TEXT(C20,"#,##0")&" SF" | E20: Comp size median SF
B21: SCA_ADJ_NARROW_LOW | D21: ="$"&TEXT(C21,"#,##0.00")&" per SF" | E21: Narrow range low — enter manually
B22: SCA_ADJ_NARROW_HIGH | D22: ="$"&TEXT(C22,"#,##0.00")&" per SF" | E22: Narrow range high — enter manually
B23: SCA_ADJ_NARROW_MEAN | D23: ="$"&TEXT(C23,"#,##0.00")&" per SF" | E23: Narrow range mean — enter manually
B24: SCA_ADJ_NARROW_MEDIAN | D24: ="$"&TEXT(C24,"#,##0.00")&" per SF" | E24: Narrow range median — enter manually
B25: SCA_ADJ_RELEVANT_MEAN | D25: ="$"&TEXT(C25,"#,##0.00")&" per SF" | E25: Most-relevant comps mean — enter manually
B26: SCA_ADJ_RELEVANT_MEDIAN | D26: ="$"&TEXT(C26,"#,##0.00")&" per SF" | E26: Most-relevant comps median — enter manually
B27: SCA_QUAL_CONCLUSION | D27: =IF(C27="","",C27) | E27: Qualitative conclusion text — enter manually
B29: OUTPUTS — CAP RATE ANALYSIS
B30: Placeholder | C30: Raw Value | D30: Report Format (→ Word) | E30: Notes
B31: Indicated Rate
B32: CAP_RATE_METHOD1 | C32: =IFERROR(AVERAGE(cap_rates!F4:F7),"") | D32: =TEXT(C32,"0.0%") | E32: Implied from comp sales
B33: Selected Rate (Report Placeholder)
B34: Placeholder | C34: Raw Value | D34: Report Format (→ Word) | E34: Notes
B35: CAP_RATE | C35: =income_summary!C19 | D35: =TEXT(C35,"0.0%") | E35: ← Set cap rate in income_summary tab (C19)
B38: PER-COMP DATA — for comp page automation
B39: Python iterates these rows (one per comp). Add/remove rows as comps change.
B40: Comp No. | C40: Sale Date | D40: Location | E40: Sale Price | F40: GBA (SF) | G40: $/SF | H40: Market Adj. | I40: Size Adj. | J40: Location Adj. | K40: Net Adj. | L40: Indicated $/SF
B41: =sales!B9 | C41: =sales!C9 | D41: =sales!D9 | E41: =sales!E9 | F41: =sales!F9 | G41: =sales!G9 | H41: =sales!D20 | I41: =sales!G20 | J41: =sales!H20 | K41: =sales!I20 | L41: =sales!J20
B42: =sales!B10 | C42: =sales!C10 | D42: =sales!D10 | E42: =sales!E10 | F42: =sales!F10 | G42: =sales!G10 | H42: =sales!D21 | I42: =sales!G21 | J42: =sales!H21 | K42: =sales!I21 | L42: =sales!J21
B43: =sales!B11 | C43: =sales!C11 | D43: =sales!D11 | E43: =sales!E11 | F43: =sales!F11 | G43: =sales!G11 | H43: =sales!D22 | I43: =sales!G22 | J43: =sales!H22 | K43: =sales!I22 | L43: =sales!J22
B44: =sales!B12 | C44: =sales!C12 | D44: =sales!D12 | E44: =sales!E12 | F44: =sales!F12 | G44: =sales!G12 | H44: =sales!D23 | I44: =sales!G23 | J44: =sales!H23 | K44: =sales!I23 | L44: =sales!J23
...

Sheet comp_data
A1: COMP_NO | B1: COMP_SUBMARKET | C1: COMP_ADDRESS_LINE1 | D1: COMP_ADDRESS_LINE2 | E1: COMP_PROPERTY_TYPE | F1: COMP_SALE_PRICE | G1: COMP_SALE_DATE | H1: COMP_GBA_SF | I1: COMP_PRICE_SF | J1: COMP_CAP_RATE | K1: COMP_YEAR_BUILT | L1: COMP_SITE_AREA | M1: COMP_STORIES | N1: COMP_CONSTRUCTION | O1: COMP_CONDITION | P1: COMP_ZONING | Q1: COMP_TOPOGRAPHY | R1: COMP_SHAPE | S1: COMP_FLOOD_ZONE | T1: COMP_ACCESS | U1: COMP_VISIBILITY | V1: COMP_UTILITIES | W1: COMP_GRANTOR | X1: COMP_GRANTEE | Y1: COMP_DEED_REF | Z1: COMP_VERIFICATION | AA1: COMP_NOI | AB1: COMP_NOI_SF | AC1: COMP_ANALYSIS | AD1: COMP_RELEVANCE | AE1: COMP_POPULATION | AF1: COMP_HH_INCOME | AG1: COMP_LIST_PRICE | AH1: COMP_PCT_DISCOUNT | AI1: COMP_TIME_ON_MARKET
A2: Sale No. N (e.g. Sale No. 1) | B2: Submarket name (e.g. Demo Hills) | C2: Street address | D2: City, State ZIP | E2: Property type label | F2: Sale price (e.g. $892,000) | G2: Sale date (e.g. 12/26/2025) | H2: GBA with SF (e.g. 9,780 SF) | I2: Price per SF (e.g. $91.26) | J2: Cap rate (e.g. 8.10% or N/A) | K2: Year built (e.g. 1988) | L2: Site area (e.g. ± 110,002 SF) | M2: Stories (e.g. One, Two) | N2: Construction type | O2: Condition (e.g. Average) | P2: Zoning (e.g. Office/Commercial) | Q2: Topography (e.g. Level) | R2: Shape (e.g. Irregular) | S2: Flood zone (e.g. Zone X) | T2: Access (e.g. Average) | U2: Visibility (e.g. Average) | V2: Utilities (e.g. All Public) | W2: Grantor name | X2: Grantee name | Y2: Deed reference number | Z2: Verification source | AA2: NOI (e.g. $72,293 or Not Available) | AB2: NOI per SF (e.g. $7.39 or Not Available) | AC2: Main analysis paragraph | AD2: Relevance sentence | AE2: Population (e.g. 132,176) | AF2: Median HH income (e.g. $94,659) | AG2: List price (e.g. $1,000,000) | AH2: % discount from list (e.g. 11%) | AI2: Time on market (e.g. 52 days)
A3: Sale No. 1
A4: Sale No. 2
A5: Sale No. 3
A6: Sale No. 4
A7: Sale No. 5
A8: Sale No. 6
A9: Sale No. 7

Sheet dilmore
A1: Dilmore Size Adjustment Table — Size Factor (A_c / A_s)
A2: A_c = Comparable GBA | A_s = Subject GBA | Factor = 1.00 means no size adjustment
A3: A_c / A_s | B3: 80% Curve | C3: 82.5% Curve | D3: 85% Curve | E3: 87.5% Curve | F3: 90% Curve | G3: Adj % (85%)
A4: 0.01 | B4: 0.23 | C4: 0.28 | D4: 0.34 | E4: 0.41 | F4: 0.5 | G4: -66.0%
A5: 0.02 | B5: 0.28 | C5: 0.34 | D5: 0.4 | E5: 0.47 | F5: 0.55 | G5: -60.0%
A6: 0.03 | B6: 0.32 | C6: 0.38 | D6: 0.44 | E6: 0.51 | F6: 0.59 | G6: -56.0%
A7: 0.04 | B7: 0.35 | C7: 0.41 | D7: 0.47 | E7: 0.54 | F7: 0.61 | G7: -53.0%
A8: 0.05 | B8: 0.38 | C8: 0.44 | D8: 0.49 | E8: 0.56 | F8: 0.63 | G8: -51.0%
A9: 0.06 | B9: 0.4 | C9: 0.46 | D9: 0.52 | E9: 0.58 | F9: 0.65 | G9: -48.0%
A10: 0.07 | B10: 0.42 | C10: 0.48 | D10: 0.54 | E10: 0.6 | F10: 0.67 | G10: -46.0%
A11: 0.08 | B11: 0.44 | C11: 0.5 | D11: 0.55 | E11: 0.61 | F11: 0.68 | G11: -45.0%
A12: 0.09 | B12: 0.46 | C12: 0.51 | D12: 0.57 | E12: 0.63 | F12: 0.69 | G12: -43.0%
A13: 0.1 | B13: 0.48 | C13: 0.53 | D13: 0.58 | E13: 0.64 | F13: 0.7 | G13: -42.0%
A14: 0.11 | B14: 0.49 | C14: 0.54 | D14: 0.6 | E14: 0.65 | F14: 0.71 | G14: -40.0%
A15: 0.12 | B15: 0.51 | C15: 0.56 | D15: 0.61 | E15: 0.66 | F15: 0.72 | G15: -39.0%
... A115: 100 | B115: 4.41 | C115: 3.59 | D115: 2.95 | E115: 2.43 | F115: 2.01 | G115: +195.0%

Sheet sca_adjustment_grid
A1: Sales Comparison Adjustment Grid — Dilmore Method
A3: Elasticity Curve: | B3: 85 | C3: ← Select: 80, 82.5, 85, 87.5, or 90
A4: Subject GBA (SF): | B4: =Intake!B32 | C4: ← Linked to Intake tab (GBA row)
A6: Comp | B6: Sale Price ($) | C6: Comp GBA (SF) | D6: Sale Price ($/SF) | E6: Sale Date | F6: Months to Eff. Date | G6: Monthly Mkt Rate | H6: Time Adj % | I6: Adjusted Price ($/SF) | J6: Ratio (Ac/As) | K6: Size Factor | L6: Size Adj % | M6: Size Adj $/SF | N6: Location Adj % | O6: Quality/Condition Adj % | P6: Utility Adj % | Q6: Net Adjustment % | R6: Indicated Value ($/SF) | S6: Notes
A7: Sale No. 1 | D7: =IF(OR(B7="",C7=""),"",B7/C7) | F7: =IF(OR(E7="",Intake!$B$9=""),"",(Intake!$B$9-E7)/30.4375) | H7: =IF(OR(F7="",G7=""),"",F7*G7) | I7: =IF(OR(D7="",H7=""),"",D7*(1+H7)) | J7: =IF(C7="","",IFERROR(C7/$B$4,"")) | M7: =IF(OR(I7="",L7=""),"",I7*L7) | Q7: =IF(L7="","",L7+SUM(N7:P7)) | R7: =IF(OR(I7="",Q7=""),"",I7*(1+Q7))
A8: Sale No. 2 | D8: =IF(OR(B8="",C8=""),"",B8/C8) | F8: =IF(OR(E8="",Intake!$B$9=""),"",(Intake!$B$9-E8)/30.4375) | H8: =IF(OR(F8="",G8=""),"",F8*G8) | I8: =IF(OR(D8="",H8=""),"",D8*(1+H8)) | J8: =IF(C8="","",IFERROR(C8/$B$4,"")) | M8: =IF(OR(I8="",L8=""),"",I8*L8) | Q8: =IF(L8="","",L8+SUM(N8:P8)) | R8: =IF(OR(I8="",Q8=""),"",I8*(1+Q8))
A9: Sale No. 3 | D9: =IF(OR(B9="",C9=""),"",B9/C9) | F9: =IF(OR(E9="",Intake!$B$9=""),"",(Intake!$B$9-E9)/30.4375) | H9: =IF(OR(F9="",G9=""),"",F9*G9) | I9: =IF(OR(D9="",H9=""),"",D9*(1+H9)) | J9: =IF(C9="","",IFERROR(C9/$B$4,"")) | M9: =IF(OR(I9="",L9=""),"",I9*L9) | Q9: =IF(L9="","",L9+SUM(N9:P9)) | R9: =IF(OR(I9="",Q9=""),"",I9*(1+Q9))
A10: Sale No. 4 | D10: =IF(OR(B10="",C10=""),"",B10/C10) | F10: =IF(OR(E10="",Intake!$B$9=""),"",(Intake!$B$9-E10)/30.4375) | H10: =IF(OR(F10="",G10=""),"",F10*G10) | I10: =IF(OR(D10="",H10=""),"",D10*(1+H10)) | J10: =IF(C10="","",IFERROR(C10/$B$4,"")) | M10: =IF(OR(I10="",L10=""),"",I10*L10) | Q10: =IF(L10="","",L10+SUM(N10:P10)) | R10: =IF(OR(I10="",Q10=""),"",I10*(1+Q10))
A11: Sale No. 5 | D11: =IF(OR(B11="",C11=""),"",B11/C11) | F11: =IF(OR(E11="",Intake!$B$9=""),"",(Intake!$B$9-E11)/30.4375) | H11: =IF(OR(F11="",G11=""),"",F11*G11) | I11: =IF(OR(D11="",H11=""),"",D11*(1+H11)) | J11: =IF(C11="","",IFERROR(C11/$B$4,"")) | M11: =IF(OR(I11="",L11=""),"",I11*L11) | Q11: =IF(L11="","",L11+SUM(N11:P11)) | R11: =IF(OR(I11="",Q11=""),"",I11*(1+Q11))
A12: Sale No. 6 | D12: =IF(OR(B12="",C12=""),"",B12/C12) | F12: =IF(OR(E12="",Intake!$B$9=""),"",(Intake!$B$9-E12)/30.4375) | H12: =IF(OR(F12="",G12=""),"",F12*G12) | I12: =IF(OR(D12="",H12=""),"",D12*(1+H12)) | J12: =IF(C12="","",IFERROR(C12/$B$4,"")) | M12: =IF(OR(I12="",L12=""),"",I12*L12) | Q12: =IF(L12="","",L12+SUM(N12:P12)) | R12: =IF(OR(I12="",Q12=""),"",I12*(1+Q12))
A13: Sale No. 7 | D13: =IF(OR(B13="",C13=""),"",B13/C13) | F13: =IF(OR(E13="",Intake!$B$9=""),"",(Intake!$B$9-E13)/30.4375) | H13: =IF(OR(F13="",G13=""),"",F13*G13) | I13: =IF(OR(D13="",H13=""),"",D13*(1+H13)) | J13: =IF(C13="","",IFERROR(C13/$B$4,"")) | M13: =IF(OR(I13="",L13=""),"",I13*L13) | Q13: =IF(L13="","",L13+SUM(N13:P13)) | R13: =IF(OR(I13="",Q13=""),"",I13*(1+Q13))
A14: Sale No. 8 | D14: =IF(OR(B14="",C14=""),"",B14/C14) | F14: =IF(OR(E14="",Intake!$B$9=""),"",(Intake!$B$9-E14)/30.4375) | H14: =IF(OR(F14="",G14=""),"",F14*G14) | I14: =IF(OR(D14="",H14=""),"",D14*(1+H14)) | J14: =IF(C14="","",IFERROR(C14/$B$4,"")) | M14: =IF(OR(I14="",L14=""),"",I14*L14) | Q14: =IF(L14="","",L14+SUM(N14:P14)) | R14: =IF(OR(I14="",Q14=""),"",I14*(1+Q14))
A15: Sale No. 9 | D15: =IF(OR(B15="",C15=""),"",B15/C15) | F15: =IF(OR(E15="",Intake!$B$9=""),"",(Intake!$B$9-E15)/30.4375) | H15: =IF(OR(F15="",G15=""),"",F15*G15) | I15: =IF(OR(D15="",H15=""),"",D15*(1+H15)) | J15: =IF(C15="","",IFERROR(C15/$B$4,"")) | M15: =IF(OR(I15="",L15=""),"",I15*L15) | Q15: =IF(L15="","",L15+SUM(N15:P15)) | R15: =IF(OR(I15="",Q15=""),"",I15*(1+Q15))
A16: Sale No. 10 | D16: =IF(OR(B16="",C16=""),"",B16/C16) | F16: =IF(OR(E16="",Intake!$B$9=""),"",(Intake!$B$9-E16)/30.4375) | H16: =IF(OR(F16="",G16=""),"",F16*G16) | I16: =IF(OR(D16="",H16=""),"",D16*(1+H16)) | J16: =IF(C16="","",IFERROR(C16/$B$4,"")) | M16: =IF(OR(I16="",L16=""),"",I16*L16) | Q16: =IF(L16="","",L16+SUM(N16:P16)) | R16: =IF(OR(I16="",Q16=""),"",I16*(1+Q16))
A18: Green cells = manual entry. Factor & Adj % columns are auto-filled automatically during validate/deliver (python axiom.py dilmore <file_no> to run standalone).
